Workbook
Name BoxPlot: "BoxPlot"
Name Bubble: "Bubble"
Name Candlestick: "Candlestick"
Name Chart: "Chart"
Name ChartImage: "ChartImage"
Name ColumnRange: "ColumnRange"
Name Dumbbell: "Dumbbell"
Name Heatmap: "Heatmap"
Name Histogram: "Histogram"
Name Map: "Map"
Name OHLC: "OHLC"
Name PieChart: "PieChart"
Name Scatter: "Scatter"
Name Series: "Series"
Name Stripe: "Stripe"
Name Table: "Table"
Name TreeMap: "TreeMap"
Name Waterfall: "Waterfall"

Sheet CDM - Q
C1: Australia | M1: Japan | R1: New Zealand | X1: Korea | AF1: United States | AZ1: Singapore | BE1: Taiwan | BI1: Thailand
C2: =_xll.CEIC.Link("db12b970-86df-4fa8-906a-ca6887c09ca1", "Series", "GDP: 2023-24p: sa") -> GDP: 2023-24p: sa | D2: =_xll.CEIC.Link("916583cc-7d50-45d0-ad3d-65ca48018c4b", "Series", "GDP: sa: 2023-24p: Non Farm") -> GDP: sa: 2023-24p: Non Farm | E2: =_xll.CEIC.Link("71555d41-89ca-4b68-9556-cc3f5c7281bc", "Series", "Unit Labour Cost: Nominal: sa") -> Unit Labour Cost: Nominal: sa | F2: Consumer Price Index (CPI): All Groups | G2: Consumer Price Index: sa | H2: Consumer Price Index: sa: Trimmed Mean | I2: =_xll.CEIC.Link("3d5dbfd6-9152-4fd7-94d1-97980d6f5dfe", "Series", "GDP: sa: Imports of Goods & Services") -> GDP: sa: Imports of Goods & Services | J2: =_xll.CEIC.Link("7bd74527-1990-4c4f-8ce7-18521f70f717", "Series", "GDP: 2023-24p: sa: Imports of Goods & Services") -> GDP: 2023-24p: sa: Imports of Goods & Services | K2: =_xll.CEIC.Link("2c48606c-97cc-4390-8424-197283ff7ffd", "Series", "Unit Labour Cost: Nominal: Non Farm: sa") -> Unit Labour Cost: Nominal: Non Farm: sa | M2: =_xll.CEIC.Link("a7e6e1a1-06e5-48f5-8ced-c20d9948b62a", "Series", "Gross Domestic Product: 2020 Market Price (2020p: sa)") -> Gross Domestic Product: 2020 Market Price (2020p: sa) | N2: (DC)GDP: 2000p: sa | O2: =_xll.CEIC.Link("cad01b68-64a4-4e9b-a447-006e4d8a3e3b", "Series", "GDP: 2020p: sa: Imports") -> GDP: 2020p: sa: Imports | P2: =_xll.CEIC.Link("05026f9c-d747-436f-953a-bb7ee8fe1c76", "Series", "GDP: sa: Imports") -> GDP: sa: Imports | R2: =_xll.CEIC.Link("7a8f9b32-6770-4612-bfec-8ad7c844272b", "Series", "Consumer Price Index (CPI)") -> Consumer Price Index (CPI) | S2: Labour Cost Index | T2: GDP: 2009-10p: Chain-Volume: sa: Imports of Goods and Services | U2: GDP: sa: Imports of Goods and Services | V2: Unemployment Rate: sa | X2: Gross Domestic Product (GDP): 2015p: sa | Y2: =_xll.CEIC.Link("9f78fb79-2d68-4e02-9c2f-6d3412befcc0", "Series", "Gross Domestic Product (GDP): 2020p: sa") -> Gross Domestic Product (GDP): 2020p: sa | Z2: Unit Labour Cost Index (ULI): Manufacturing | AA2: Unit Labour Cost Index (ULI): Manufacturing | AB2: =_xll.CEIC.Link("0f0ec87c-d4da-4cbb-acbd-0b1830eccdc7", "Series", "Unit Labour Cost Index (ULI): Manufacturing") -> Unit Labour Cost Index (ULI): Manufacturing | AC2: GDP: 2020p: sa: Imports of Goods & Services | AD2: GDP: sa: Imports of Goods & Services | AF2: =_xll.CEIC.Link("f9fc37fa-7721-42ca-b29f-ada83ba9916e", "Series", "Gross Domestic Product: 2017p: saar") -> Gross Domestic Product: 2017p: saar | AH2: =_xll.CEIC.Link("32aabc4e-80eb-46a0-a426-452304a785aa", "Series", "GDP: saar: NE: Imports: Goods") -> GDP: saar: NE: Imports: Goods | AI2: FT: saar: Imports: Nonpetroleum Goods | AJ2: FT: saar: Imp: Gds: CPG: Computers, Peripherals & Parts (CP) | AK2: FT: saar: Imp: Gds: CPG: Others | AL2: FT: saar: Imp: Gds: CPG: Oth: Semiconductors & Related Devices | AN2: =_xll.CEIC.Link("54c3e2be-9d5c-4cce-9b9c-4c0ff2a672be", "Series", "GDP: PI: sa: Import: Goods") -> GDP: PI: sa: Import: Goods | AO2: FT: PI: sa: Imports: Nonpetroleum Goods | AP2: FT: PI: sa: Imports: Goods: CPG: Computers, Peripherals & Parts (CP) | AQ2: FT: PI: sa: Imports: Goods: CPG: Other | AR2: FT: PI: sa: Imports: Goods: CPG: Oth: Semiconductors & Rel Devices | AT2: =_xll.CEIC.Link("68084f10-ff53-4932-bcea-941ae142a918", "Series", "FT: PI: sa: Imports: Goods: IS: ND: Petroleum & Pdts") -> FT: PI: sa: Imports: Goods: IS: ND: Petroleum & Pdts | AV2: =_xll.CEIC.Link("2981f81c-fa0e-4c5d-a6da-4d789f3c9bef", "Series", "Productivity & Cost Index: saar: Business: Unit Labour Costs") -> Productivity & Cost Index: saar: Business: Unit Labour Costs | AW2: GDP: 2017p: saar: NE: Imports | AX2: GDP: saar: NE: Imports | AZ2: =_xll.CEIC.Link("20cb9d9b-9ead-43bc-b9aa-b5274e445e15", "Series", "GDP: Imports of Goods & Services") -> GDP: Imports of Goods & Services | BA2: GDP: 2015p: Import of Goods & Services | BB2: GDP: 2015p: sa: Import of Goods & Services | BC2: Unit Labour Cost of Overall Economy: 2015=100 | BE2: =_xll.CEIC.Link("9c397ca4-8e13-430f-96d9-508786a53bb0", "Series", "GDP: 2021p: sa") -> GDP: 2021p: sa | BF2: =_xll.CEIC.Link("610f759b-14fd-4389-b6ed-6980afa3ce95", "Series", "Unemployment Rate: Quarterly: sa: Taiwan") -> Unemployment Rate: Quarterly: sa: Taiwan | BG2: =_xll.CEIC.Link("7b4f32e2-bec8-4fee-a506-1864ee9a3291", "Series", "GDP: Deflator: Imports") -> GDP: Deflator: Imports | BI2: =_xll.CEIC.Link("f545662e-a93f-4d0a-815b-c1bfdae740a0", "Series", "Gross Domestic Product: 2002p: Chain Volume Measures (CVM)") -> Gross Domestic Product: 2002p: Chain Volume Measures (CVM)
B3: Date | C3: 576159347 | D3: 576355377 | E3: 584492247 | F3: Linked | G3: Linked | H3: Linked | I3: 262451801 | J3: 576159327 | K3: 584492307 | M3: 676288387 (JAYAIDAAAABKZF) | N3: 81204101 (JAKX) | O3: 676290657 (JAYAIDAAAABLIX) | P3: 676290437 (JAYAIDAAAABLHH) | R3: 399976317 | S3: 227871202 | T3: 360405607 | U3: 360405487 | V3: 197638902 | X3: 401451117 (KAZAJKBAAAARGK) | Y3: 528868767 (KAZAJKBAAAATPK) | Z3: 193656302 (KGYCAF) | AA3: 353772902 (KGYEAC) | AB3: 537033597 (KGYEACXAAAARDE) | AC3: 528868727 (KAZAJKBAAAATTI) | AD3: 354239117 (KAZAJKBAAAAAGA) | AF3: 511279457 (UAZCSDBAAADDME) | AH3: 511278707 (UAZCSDBAAADEIA) | AI3: 511478117 (UAZCSDBAAADKFE) | AJ3: 511477397 (UAZCSDBAAADKCK) | AK3: 511477427 (UAZCSDBAAADKCN) | AL3: 511477467 (UAZCSDBAAADKCR) | AN3: 511278087 (UAZCSDBAAADEFQ) | AO3: 511476107 (UAZCSDBAAADJXV) | AP3: 511475387 (UAZCSDBAAADJVB) | AQ3: 511475417 (UAZCSDBAAADJVE) | AR3: 511475457 (UAZCSDBAAADJVI) | AT3: 511475277 (UAZCSDBAAADJUQ) | AV3: 521985837 (UGTEWBAAAABBJO) | AW3: 511279937 (UAZCSDBAAADDOA) | AX3: 511278697 (UAZCSDBAAADEHZ) | AZ3: 383937127 (SAZGAAAAAAAALZ) | BA3: 414324517 (SAZGAAAAAAABMX) | BB3: 414337237 (SAZGAAAAAAABQZ) | BC3: 479914577 (SAZGAAAAAAACOB) | BE3: 530108807 (WABNAA) | BF3: 409151467 | BG3: 530154257 (WABRAAE) | BI3: 367505847 (TAZZNAAAAAAACP)
A4: 1948 | B4: 17593 | R4: 26.849028 | AF4: 2239.682 | AH4: 7.34 | AN4: 17.505 | AV4: 17.043 | AW4: 57.862 | AX4: 9.624
B5: 17685 | R5: 27.159541 | AF5: 2276.69 | AH5: 7.644 | AN5: 17.561 | AV5: 16.89 | AW5: 60.156 | AX5: 10.036
B6: 17777 | R6: 27.345849 | AF6: 2289.77 | AH6: 7.708 | AN6: 17.341 | AV6: 17.44 | AW6: 63.297 | AX6: 10.456
B7: 17868 | R7: 27.407952 | AF7: 2292.364 | AH7: 7.536 | AN7: 17.004 | AV7: 17.704 | AW7: 62.27 | AX7: 10.124
A8: 1949 | B8: 17958 | R8: 27.407952 | AF8: 2260.807 | AH8: 7.164 | AN8: 16.592 | AV8: 17.403 | AW8: 60.402 | AX8: 9.604
B9: 18050 | R9: 27.462768 | AF9: 2253.128 | AH9: 6.852 | AN9: 16.397 | AV9: 17.167 | AW9: 59.521 | AX9: 9.364
B10: 18142 | R10: 27.791663 | AF10: 2276.424 | AH10: 6.62 | AN10: 16.316 | AV10: 16.913 | AW10: 57.095 | AX10: 8.936
B11: 18233 | R11: 27.901294 | AF11: 2257.352 | AH11: 6.86 | AN11: 16.403 | AV11: 17.03 | AW11: 57.955 | AX11: 9.092
A12: 1950 | B12: 18323 | R12: 27.956111 | AF12: 2346.104 | AH12: 7.184 | AN12: 16.861 | AV12: 16.867 | AW12: 59.575 | AX12: 9.501
B13: 18415 | R13: 28.833165 | AF13: 2417.682 | AH13: 7.808 | AN13: 17.299 | AV13: 16.878 | AW13: 62.863 | AX13: 10.229
B14: 18507 | R14: 29.792444 | AF14: 2511.127 | AH14: 10.464 | AN14: 17.966 | AV14: 16.91 | AW14: 77.573 | AX14: 13.033
B15: 18598 | R15: 30.285786 | AF15: 2559.214 | AH15: 10.868 | AN15: 18.95 | AV15: 17.137 | AW15: 77.719 | AX15: 13.685
A16: 1951 | B16: 18688 | R16: 30.724314 | AF16: 2593.967 | AH16: 11.772 | AN16: 20.811 | AV16: 17.741 | AW16: 77.724 | AX16: 14.866
B17: 18780 | R17: 32.039896 | AF17: 2638.898 | AH17: 12.04 | AN17: 22.188 | AV17: 18.176 | AW17: 75.148 | AX17: 15.178
B18: 18872 | R18: 33.081397 | AF18: 2693.259 | AH18: 10.808 | AN18: 23.025 | AV18: 17.932 | AW18: 68.784 | AX18: 14.31
B19: 18963 | R19: 33.903636 | AF19: 2699.156 | AH19: 10.084 | AN19: 23.21 | AV19: 18.215 | AW19: 66.985 | AX19: 13.99
A20: 1952 | B20: 19054 | R20: 34.342163 | AF20: 2727.954 | AH20: 10.696 | AN20: 21.79 | AV20: 18.266 | AW20: 74.757 | AX20: 14.958
B21: 19146 | R21: 34.808099 | AF21: 2733.8 | AH21: 10.604 | AN21: 21.412 | AV21: 18.467 | AW21: 74.371 | AX21: 14.63
B22: 19238 | R22: 35.19181 | AF22: 2753.517 | AH22: 10.768 | AN22: 20.999 | AV22: 18.73 | AW22: 78.921 | AX22: 15.25
B23: 19329 | R23: 35.465889 | AF23: 2843.941 | AH23: 11.284 | AN23: 20.631 | AV23: 18.855 | AW23: 85.997 | AX23: 16.342
A24: 1953 | B24: 19419 | R24: 35.822192 | AF24: 2896.811 | AH24: 10.988 | AN24: 20.453 | AV24: 18.881 | AW24: 83.877 | AX24: 15.795
B25: 19511 | R25: 36.233312 | AF25: 2919.206 | AH25: 11.516 | AN25: 20.265 | AV25: 18.907 | AW25: 88.227 | AX25: 16.447
B26: 19603 | R26: 36.644431 | AF26: 2902.785 | AH26: 11.152 | AN26: 20.211 | AV26: 19.196 | AW26: 87.891 | AX26: 16.307
B27: 19694 | R27: 37.439262 | AF27: 2858.845 | AH27: 10.244 | AN27: 20.268 | AV27: 19.232 | AW27: 83.568 | AX27: 15.507
A28: 1954 | B28: 19784 | R28: 37.74075 | AF28: 2845.192 | AH28: 9.976 | AN28: 20.521 | AV28: 19.35 | AW28: 78.742 | AX28: 14.78
B29: 19876 | R29: 38.371132 | AF29: 2848.305 | AH29: 11.048 | AN29: 20.665 | AV29: 19.37 | AW29: 85.824 | AX29: 16.184
B30: 19968 | R30: 38.425948 | AF30: 2880.482 | AH30: 10.224 | AN30: 20.862 | AV30: 19.116 | AW30: 80.647 | AX30: 15.304
B31: 20059 | R31: 38.343724 | AF31: 2936.852 | AH31: 10.164 | AN31: 20.892 | AV31: 19.114 | AW31: 81.412 | AX31: 15.46
A32: 1955 | B32: 20149 | R32: 38.864476 | AF32: 3020.746 | AH32: 11.104 | AN32: 20.611 | AV32: 18.73 | AW32: 86.223 | AX32: 16.169
B33: 20241 | M33: 43911.243 | O33: 1553.4254 | P33: 843.73748 | R33: 39.248187 | AF33: 3069.91 | AH33: 11.232 | AN33: 20.644 | AV33: 18.791 | AW33: 91.112 | AX33: 17.097
B34: 20333 | M34: 45736.018 | O34: 1557.3409 | P34: 871.55075 | R34: 39.303002 | AF34: 3111.379 | AH34: 11.296 | AN34: 20.698 | AV34: 18.923 | AW34: 92.645 | AX34: 17.421
B35: 20424 | M35: 46456.716 | O35: 1861.2878 | P35: 1028.8856 | R35: 39.303002 | AF35: 3130.068 | AH35: 12.476 | AN35: 20.764 | AV35: 19.213 | AW35: 96.002 | AX35: 18.109
A36: 1956 | B36: 20515 | M36: 48191.969 | O36: 1806.927 | P36: 1020.9829 | R36: 39.702884 | AF36: 3117.922 | AH36: 13.02 | AN36: 20.829 | AV36: 19.784 | AW36: 100.032 | AX36: 18.925
B37: 20607 | M37: 48392.168 | O37: 1947.6094 | P37: 1115.0964 | R37: 40.251591 | AF37: 3143.694 | AH37: 12.692 | AN37: 21.009 | AV37: 20.064 | AW37: 99.511 | AX37: 18.973
B38: 20699 | M38: 48708.622 | O38: 2179.7127 | P38: 1267.6075 | R38: 41.113846 | AF38: 3140.874 | AH38: 12.62 | AN38: 21.13 | AV38: 20.271 | AW38: 100.376 | AX38: 19.253
B39: 20790 | M39: 49250.66 | O39: 2392.603 | P39: 1432.9477 | R39: 41.113846 | AF39: 3192.57 | AH39: 12.88 | AN39: 21.373 | AV39: 20.31 | AW39: 95.771 | AX39: 18.541
A40: 1957 | B40: 20880 | M40: 50651.766 | O40: 2586.8267 | P40: 1617.3773 | R40: 40.800299 | AF40: 3213.011 | AH40: 13.188 | AN40: 21.408 | AV40: 20.582 | AW40: 103.391 | AX40: 20.1
...

Sheet CDM - M
C1: Australia | E1: Japan | G1: United States | J1: Korea | M1: Taiwan | Q1: India
C2: =_xll.CEIC.Link("c129f249-dc89-4599-a62a-d354b1877a9e", "Series", "Unemployment Rate: Monthly: sa: Australia") -> Unemployment Rate: Monthly: sa: Australia | E2: Labour Productivity Index (LPI): Manufacturing (Mfg) | G2: Policy Rate: Month End: United States: Federal Funds Rate | H2: PCE: PI: sa: excl Food & Energy | J2: Policy Rate: Month End: Base Rate: Bank of Korea | K2: Unemployment Rate | M2: =_xll.CEIC.Link("ea131218-bb06-4e5d-9f7f-ee7c6ad9a92e", "Series", "Consumer Price Index: Seasonally Adjusted") -> Consumer Price Index: Seasonally Adjusted | N2: =_xll.CEIC.Link("f3f1afd8-7e0b-4e66-bcdc-ee7d884dbe2a", "Series", "Unit Output Labor Cost Index: Industry (ID)") -> Unit Output Labor Cost Index: Industry (ID) | O2: =_xll.CEIC.Link("993ca365-589c-4708-81cc-64bd9ddf66ce", "Series", "Policy Rate: Month End: Discount Rate") -> Policy Rate: Month End: Discount Rate | Q2: =_xll.CEIC.Link("feac2130-cfdd-45b8-8d57-2d7cf9b8a97d", "Series", "SPF: CPI Combined: Headline: Current Fiscal Year: Mean") -> SPF: CPI Combined: Headline: Current Fiscal Year: Mean
B3: Date | C3: 450248027 | E3: 509218357 (JGXCAZJAAAASBF) | G3: 456107507 | H3: 511285287 (UIKBACHAAAAMKM) | J3: 30189201 (KMFC) | K3: 224917301 | M3: 503425687 (WIHJA) | N3: 508773667 (WGVTAA) | O3: 45972101 (WMAD) | Q3: %
A4: 1948 | B4: 17533 | Q4: 413887677 (ISAAAALNAAAAYX)
B5: 17564 | Q5: 4.3
B6: 17593
B7: 17624 | Q7: 3.4
B8: 17654
B9: 17685 | Q9: 3.6
B10: 17715
B11: 17746 | Q11: 3.5
B12: 17777
B13: 17807 | Q13: 3.8
B14: 17838
B15: 17868 | Q15: 3.7
A16: 1949 | B16: 17899
B17: 17930 | Q17: 4.7
B18: 17958
B19: 17989 | Q19: 4.7
B20: 18019
B21: 18050 | Q21: 4.5
B22: 18080
B23: 18111 | Q23: 4.1
B24: 18142
B25: 18172 | Q25: 3.6
B26: 18203
B27: 18233 | Q27: 3.5
A28: 1950 | B28: 18264
B29: 18295 | Q29: 3.8
B30: 18323
B31: 18354 | Q31: 3.6
B32: 18384
B33: 18415 | Q33: 3.6
B34: 18445
B35: 18476 | Q35: 3.9
B36: 18507
B37: 18537 | Q37: 4.6
B38: 18568
B39: 18598 | Q39: 4.8
A40: 1951 | B40: 18629
...

Sheet CDM - D
C1: =_xll.CEIC.Link("dc6f7b84-d40a-4805-8f1e-5277c5dd5bd8", "Series", "(DC)OxCGRT: Stringency Index: Australia") -> (DC)OxCGRT: Stringency Index: Australia | D1: (DC)OxCGRT: Stringency Index: New Zealand | E1: (DC)OxCGRT: Stringency Index: Japan | F1: (DC)OxCGRT: Stringency Index: South Korea | G1: (DC)OxCGRT: Stringency Index: United States | H1: (DC)OxCGRT: Stringency Index: Singapore | I1: =_xll.CEIC.Link("98505fdc-78bf-42eb-b555-64f4b111ac39", "Series", "(DC)OxCGRT: Stringency Index: Taiwan") -> (DC)OxCGRT: Stringency Index: Taiwan | J1: =_xll.CEIC.Link("d2abc0ae-0a0b-4457-bd27-0edb6530f53b", "Series", "(DC)OxCGRT: Stringency Index: Thailand") -> (DC)OxCGRT: Stringency Index: Thailand
B2: Date | C2: 450498717 | D2: 450499727 | E2: 450499427 | F2: 450500047 | G2: 450500267 | H2: 450499987 | I2: 450500137 | J2: Index
A3: =YEAR(B3) -> 2020 | B3: 43831 | C3: 0 | D3: 0 | E3: 0 | F3: 0 | G3: 0 | H3: 0 | I3: 2.78 | J3: 450500167
B4: 43832 | C4: 0 | D4: 0 | E4: 0 | F4: 0 | G4: 0 | H4: 13.89 | I4: 8.33 | J4: 0
B5: 43833 | C5: 0 | D5: 0 | E5: 0 | F5: 0 | G5: 0 | H5: 13.89 | I5: 8.33 | J5: 0
B6: 43834 | C6: 0 | D6: 0 | E6: 0 | F6: 0 | G6: 0 | H6: 13.89 | I6: 8.33 | J6: 0
B7: 43835 | C7: 0 | D7: 0 | E7: 0 | F7: 0 | G7: 0 | H7: 13.89 | I7: 8.33 | J7: 0
B8: 43836 | C8: 0 | D8: 0 | E8: 0 | F8: 0 | G8: 0 | H8: 13.89 | I8: 8.33 | J8: 0
B9: 43837 | C9: 0 | D9: 0 | E9: 2.78 | F9: 0 | G9: 0 | H9: 13.89 | I9: 8.33 | J9: 0
B10: 43838 | C10: 0 | D10: 0 | E10: 2.78 | F10: 0 | G10: 0 | H10: 13.89 | I10: 8.33 | J10: 0
B11: 43839 | C11: 0 | D11: 0 | E11: 2.78 | F11: 0 | G11: 0 | H11: 13.89 | I11: 8.33 | J11: 0
B12: 43840 | C12: 0 | D12: 0 | E12: 2.78 | F12: 0 | G12: 0 | H12: 13.89 | I12: 8.33 | J12: 0
B13: 43841 | C13: 0 | D13: 0 | E13: 2.78 | F13: 0 | G13: 0 | H13: 13.89 | I13: 8.33 | J13: 0
B14: 43842 | C14: 0 | D14: 0 | E14: 2.78 | F14: 0 | G14: 0 | H14: 13.89 | I14: 8.33 | J14: 0
B15: 43843 | C15: 0 | D15: 0 | E15: 2.78 | F15: 0 | G15: 0 | H15: 13.89 | I15: 8.33 | J15: 0
... B368: 44196 | C368: 70.83 | D368: 22.22 | E368: 45.37 | F368: 68.98 | G368: 71.76 | H368: 50.93 | I368: 19.44 | J368: 63.89
A369: =YEAR(B369) -> 2021 | B369: 44197 | C369: 70.83 | D369: 22.22 | E369: 48.15 | F369: 60.65 | G369: 71.76 | H369: 50.93 | I369: 19.44 | J369: 63.89
B370: 44198 | C370: 70.83 | D370: 22.22 | E370: 48.15 | F370: 62.04 | G370: 71.76 | H370: 50.93 | I370: 19.44 | J370: 63.89
B371: 44199 | C371: 70.83 | D371: 22.22 | E371: 48.15 | F371: 62.04 | G371: 71.76 | H371: 50.93 | I371: 19.44 | J371: 63.89
B372: 44200 | C372: 70.83 | D372: 22.22 | E372: 48.15 | F372: 62.04 | G372: 71.76 | H372: 50.93 | I372: 19.44 | J372: 63.89
B373: 44201 | C373: 70.83 | D373: 22.22 | E373: 49.54 | F373: 67.59 | G373: 71.76 | H373: 50.93 | I373: 19.44 | J373: 63.89
B374: 44202 | C374: 70.83 | D374: 22.22 | E374: 49.54 | F374: 67.59 | G374: 71.76 | H374: 50.93 | I374: 19.44 | J374: 63.89
B375: 44203 | C375: 70.83 | D375: 22.22 | E375: 49.54 | F375: 63.89 | G375: 71.76 | H375: 50.93 | I375: 19.44 | J375: 63.89
B376: 44204 | C376: 70.83 | D376: 22.22 | E376: 49.54 | F376: 63.89 | G376: 71.76 | H376: 50.93 | I376: 19.44 | J376: 63.89
B377: 44205 | C377: 70.83 | D377: 22.22 | E377: 49.54 | F377: 63.89 | G377: 71.76 | H377: 50.93 | I377: 19.44 | J377: 63.89
B378: 44206 | C378: 70.83 | D378: 22.22 | E378: 49.54 | F378: 63.89 | G378: 71.76 | H378: 50.93 | I378: 19.44 | J378: 63.89
B379: 44207 | C379: 55.09 | D379: 22.22 | E379: 49.54 | F379: 63.89 | G379: 71.76 | H379: 50.93 | I379: 19.44 | J379: 63.89
B380: 44208 | C380: 55.09 | D380: 22.22 | E380: 49.54 | F380: 63.89 | G380: 71.76 | H380: 50.93 | I380: 19.44 | J380: 63.89
B381: 44209 | C381: 55.09 | D381: 22.22 | E381: 49.54 | F381: 63.89 | G381: 71.76 | H381: 50.93 | I381: 19.44 | J381: 63.89
... B733: 44561 | C733: 56.94 | D733: 62.96 | E733: 47.22 | F733: 50.93 | G733: 58.8 | H733: 48.15 | I733: 20.37 | J733: 43.52
A734: =YEAR(B734) -> 2022 | B734: 44562 | C734: 56.94 | D734: 62.96 | E734: 47.22 | F734: 50.93 | G734: 58.8 | H734: 53.7 | I734: 20.37 | J734: 43.52
B735: 44563 | C735: 56.94 | D735: 62.96 | E735: 47.22 | F735: 50.93 | G735: 58.8 | H735: 53.7 | I735: 20.37 | J735: 43.52
B736: 44564 | C736: 56.94 | D736: 62.96 | E736: 47.22 | F736: 50.93 | G736: 58.8 | H736: 53.7 | I736: 20.37 | J736: 43.52
B737: 44565 | C737: 56.94 | D737: 62.96 | E737: 47.22 | F737: 50.93 | G737: 58.8 | H737: 53.7 | I737: 20.37 | J737: 50.93
B738: 44566 | C738: 56.94 | D738: 62.96 | E738: 47.22 | F738: 50.93 | G738: 58.8 | H738: 53.7 | I738: 20.37 | J738: 50.93
B739: 44567 | C739: 62.5 | D739: 62.96 | E739: 47.22 | F739: 50.93 | G739: 58.8 | H739: 53.7 | I739: 20.37 | J739: 50.93
B740: 44568 | C740: 62.5 | D740: 62.96 | E740: 47.22 | F740: 50.93 | G740: 58.8 | H740: 53.7 | I740: 20.37 | J740: 50.93
B741: 44569 | C741: 62.5 | D741: 62.96 | E741: 47.22 | F741: 50.93 | G741: 58.8 | H741: 53.7 | I741: 20.37 | J741: 50.93
B742: 44570 | C742: 62.5 | D742: 62.96 | E742: 47.22 | F742: 50.93 | G742: 58.8 | H742: 53.7 | I742: 20.37 | J742: 50.93
B743: 44571 | C743: 62.5 | D743: 62.96 | E743: 47.22 | F743: 50.93 | G743: 58.8 | H743: 53.7 | I743: 20.37 | J743: 50.93
...

Sheet AU - Q
C1: GDP: sa: 2022-23p | D1: GDP: sa: 2022-23p: Non Farm | E1: Import Price Deflator | F1: Consumer Price Index (CPI): All Groups | G1: CPI from 1970 Onwards | H1: CPI Trimmed Means Spliced | I1: CPI Core Index | J1: CPI Core Inflation Annualised | K1: CPI Core Moving Average | L1: Unemployment | M1: Covid Stringency Index | N1: Nominal Unit Labour Costs non-farm (s.a) | O1: Expectations Melb | P1: Expectations Union | Q1: Expectations Combined | R1: Interest | S1: SSR | T1: CPI Core Inflation Forecast | U1: Real GNI (s.a.)
B2: Date | F2: NSA | G2: WCA sa - don’t drag down! | I2: sa tax adj
A3: 1948 | B3: 17593 | M3: 0
B4: 17685 | M4: 0
B5: 17777 | M5: 0
B6: 17868 | M6: 0
A7: 1949 | B7: 17958 | M7: 0
B8: 18050 | M8: 0
B9: 18142 | M9: 0
B10: 18233 | M10: 0
A11: 1950 | B11: 18323 | M11: 0
B12: 18415 | M12: 0
B13: 18507 | M13: 0
B14: 18598 | M14: 0
A15: 1951 | B15: 18688 | M15: 0
B16: 18780 | M16: 0
B17: 18872 | M17: 0
B18: 18963 | M18: 0
A19: 1952 | B19: 19054 | M19: 0
B20: 19146 | M20: 0
B21: 19238 | M21: 0
B22: 19329 | M22: 0
A23: 1953 | B23: 19419 | M23: 0
B24: 19511 | M24: 0
B25: 19603 | M25: 0
B26: 19694 | M26: 0
A27: 1954 | B27: 19784 | M27: 0
B28: 19876 | M28: 0
B29: 19968 | M29: 0
B30: 20059 | M30: 0
A31: 1955 | B31: 20149 | M31: 0
B32: 20241 | M32: 0
B33: 20333 | M33: 0
B34: 20424 | M34: 0
A35: 1956 | B35: 20515 | M35: 0
B36: 20607 | M36: 0
B37: 20699 | M37: 0
B38: 20790 | M38: 0
A39: 1957 | B39: 20880 | M39: 0
B40: 20972 | M40: 0
...

Sheet AU - M
C1: Unemployment Rate: Monthly: sa: Australia | D1: RBA Cash Rate | E1: SSR Spliced
B2: Date
A3: 1948 | B3: 17533
B4: 17564
B5: 17593
B6: 17624
B7: 17654
B8: 17685
B9: 17715
B10: 17746
B11: 17777
B12: 17807
B13: 17838
B14: 17868
A15: 1949 | B15: 17899
B16: 17930
B17: 17958
B18: 17989
B19: 18019
B20: 18050
B21: 18080
B22: 18111
B23: 18142
B24: 18172
B25: 18203
B26: 18233
A27: 1950 | B27: 18264
B28: 18295
B29: 18323
B30: 18354
B31: 18384
B32: 18415
B33: 18445
B34: 18476
B35: 18507
B36: 18537
B37: 18568
B38: 18598
A39: 1951 | B39: 18629
B40: 18660
...

Sheet AU Edits
C1: CPI All Excl Food and Energy
B2: Date | C2: Index | D2: Tax | F2: Tax Adjusted | G2: Sa
A3: 1975 | B3: 27454
B4: 27546
B5: 27638
B6: 27729
A7: 1976 | B7: 27820
B8: 27912
B9: 28004
B10: 28095
A11: 1977 | B11: 28185
B12: 28277
B13: 28369
B14: 28460
A15: 1978 | B15: 28550
B16: 28642
B17: 28734
B18: 28825
A19: 1979 | B19: 28915
B20: 29007
B21: 29099
B22: 29190
A23: 1980 | B23: 29281
B24: 29373
B25: 29465
B26: 29556
A27: 1981 | B27: 29646
B28: 29738
B29: 29830
B30: 29921
A31: 1982 | B31: 30011
B32: 30103
B33: 30195
B34: 30286
A35: 1983 | B35: 30376
B36: 30468
B37: 30560
B38: 30651
A39: 1984 | B39: 30742
B40: 30834
...

Sheet JN - Q
C1: Real GDP: 2020p | D1: Gross Domestic Product: Seasonally Adjusted (sa) (Japan) | E1: Unit Labour Cost: Nominal | F1: Unit Labour Cost: Nominal | G1: JN Core CPI | H1: JN Core Core CPI | I1: Core Core CPI Forecast | J1: Unemployment | K1: Expectations | L1: Covid Stringency Index | M1: Import Price Deflator | N1: Interest | O1: SSR | S1: Japan Inflation YoY
B2: Date | D2: Nominal | E2: nsa | F2: sa | S2: Core+2
A3: 1980 | B3: 29281 | C3: ='CDM - Q'!M132 -> 277749.49 | G3: =AVERAGEIFS('JN - M'!D:D,'JN - M'!$B:$B,">="&EDATE('JN - Q'!$B3,-2),'JN - M'!$B:$B,"<="&EOMONTH('JN - Q'!$B3,0)) -> 77.581051 | H3: =AVERAGEIFS('JN - M'!E:E,'JN - M'!$B:$B,">="&EDATE('JN - Q'!$B3,-2),'JN - M'!$B:$B,"<="&EOMONTH('JN - Q'!$B3,0)) -> 77.620409 | I3: =AVERAGEIFS('JN - M'!F:F,'JN - M'!$B:$B,">="&EDATE('JN - Q'!$B3,-2),'JN - M'!$B:$B,"<="&EOMONTH('JN - Q'!$B3,0)) -> 77.620409 | J3: =AVERAGEIFS('JN - M'!K:K,'JN - M'!$B:$B,">="&EDATE('JN - Q'!$B3,-2),'JN - M'!$B:$B,"<="&EOMONTH('JN - Q'!$B3,0)) -> 1.8829931 | L3: 0 | N3: =AVERAGEIFS('JN - M'!I:I,'JN - M'!$B:$B,">="&EDATE('JN - Q'!$B3,-2),'JN - M'!$B:$B,"<="&EOMONTH('JN - Q'!$B3,0)) -> 9.1755667 | O3: =AVERAGEIFS('JN - M'!J:J,'JN - M'!$B:$B,">="&EDATE('JN - Q'!$B3,-2),'JN - M'!$B:$B,"<="&EOMONTH('JN - Q'!$B3,0)) -> 11.365418
B4: 29373 | C4: ='CDM - Q'!M133 -> 276285.32 | G4: =AVERAGEIFS('JN - M'!D:D,'JN - M'!$B:$B,">="&EDATE('JN - Q'!$B4,-2),'JN - M'!$B:$B,"<="&EOMONTH('JN - Q'!$B4,0)) -> 80.011111 | H4: =AVERAGEIFS('JN - M'!E:E,'JN - M'!$B:$B,">="&EDATE('JN - Q'!$B4,-2),'JN - M'!$B:$B,"<="&EOMONTH('JN - Q'!$B4,0)) -> 79.950131 | I4: =AVERAGEIFS('JN - M'!F:F,'JN - M'!$B:$B,">="&EDATE('JN - Q'!$B4,-2),'JN - M'!$B:$B,"<="&EOMONTH('JN - Q'!$B4,0)) -> 79.950131 | J4: =AVERAGEIFS('JN - M'!K:K,'JN - M'!$B:$B,">="&EDATE('JN - Q'!$B4,-2),'JN - M'!$B:$B,"<="&EOMONTH('JN - Q'!$B4,0)) -> 1.9402977 | L4: 0 | N4: =AVERAGEIFS('JN - M'!I:I,'JN - M'!$B:$B,">="&EDATE('JN - Q'!$B4,-2),'JN - M'!$B:$B,"<="&EOMONTH('JN - Q'!$B4,0)) -> 12.471667 | O4: =AVERAGEIFS('JN - M'!J:J,'JN - M'!$B:$B,">="&EDATE('JN - Q'!$B4,-2),'JN - M'!$B:$B,"<="&EOMONTH('JN - Q'!$B4,0)) -> 13.210224
B5: 29465 | C5: ='CDM - Q'!M134 -> 282473.93 | G5: =AVERAGEIFS('JN - M'!D:D,'JN - M'!$B:$B,">="&EDATE('JN - Q'!$B5,-2),'JN - M'!$B:$B,"<="&EOMONTH('JN - Q'!$B5,0)) -> 81.159659 | H5: =AVERAGEIFS('JN - M'!E:E,'JN - M'!$B:$B,">="&EDATE('JN - Q'!$B5,-2),'JN - M'!$B:$B,"<="&EOMONTH('JN - Q'!$B5,0)) -> 80.874623 | I5: =AVERAGEIFS('JN - M'!F:F,'JN - M'!$B:$B,">="&EDATE('JN - Q'!$B5,-2),'JN - M'!$B:$B,"<="&EOMONTH('JN - Q'!$B5,0)) -> 80.874623 | J5: =AVERAGEIFS('JN - M'!K:K,'JN - M'!$B:$B,">="&EDATE('JN - Q'!$B5,-2),'JN - M'!$B:$B,"<="&EOMONTH('JN - Q'!$B5,0)) -> 2.060493 | L5: 0 | N5: =AVERAGEIFS('JN - M'!I:I,'JN - M'!$B:$B,">="&EDATE('JN - Q'!$B5,-2),'JN - M'!$B:$B,"<="&EOMONTH('JN - Q'!$B5,0)) -> 12.063833 | O5: =AVERAGEIFS('JN - M'!J:J,'JN - M'!$B:$B,">="&EDATE('JN - Q'!$B5,-2),'JN - M'!$B:$B,"<="&EOMONTH('JN - Q'!$B5,0)) -> 12.778239
B6: 29556 | C6: ='CDM - Q'!M135 -> 288477.88 | G6: =AVERAGEIFS('JN - M'!D:D,'JN - M'!$B:$B,">="&EDATE('JN - Q'!$B6,-2),'JN - M'!$B:$B,"<="&EOMONTH('JN - Q'!$B6,0)) -> 82.102485 | H6: =AVERAGEIFS('JN - M'!E:E,'JN - M'!$B:$B,">="&EDATE('JN - Q'!$B6,-2),'JN - M'!$B:$B,"<="&EOMONTH('JN - Q'!$B6,0)) -> 82.094954 | I6: =AVERAGEIFS('JN - M'!F:F,'JN - M'!$B:$B,">="&EDATE('JN - Q'!$B6,-2),'JN - M'!$B:$B,"<="&EOMONTH('JN - Q'!$B6,0)) -> 82.094954 | J6: =AVERAGEIFS('JN - M'!K:K,'JN - M'!$B:$B,">="&EDATE('JN - Q'!$B6,-2),'JN - M'!$B:$B,"<="&EOMONTH('JN - Q'!$B6,0)) -> 2.1733967 | L6: 0 | N6: =AVERAGEIFS('JN - M'!I:I,'JN - M'!$B:$B,">="&EDATE('JN - Q'!$B6,-2),'JN - M'!$B:$B,"<="&EOMONTH('JN - Q'!$B6,0)) -> 10.008167 | O6: =AVERAGEIFS('JN - M'!J:J,'JN - M'!$B:$B,">="&EDATE('JN - Q'!$B6,-2),'JN - M'!$B:$B,"<="&EOMONTH('JN - Q'!$B6,0)) -> 10.600838
A7: 1981 | B7: 29646 | C7: ='CDM - Q'!M136 -> 290246.47 | G7: =AVERAGEIFS('JN - M'!D:D,'JN - M'!$B:$B,">="&EDATE('JN - Q'!$B7,-2),'JN - M'!$B:$B,"<="&EOMONTH('JN - Q'!$B7,0)) -> 82.88134 | H7: =AVERAGEIFS('JN - M'!E:E,'JN - M'!$B:$B,">="&EDATE('JN - Q'!$B7,-2),'JN - M'!$B:$B,"<="&EOMONTH('JN - Q'!$B7,0)) -> 82.279852 | I7: =AVERAGEIFS('JN - M'!F:F,'JN - M'!$B:$B,">="&EDATE('JN - Q'!$B7,-2),'JN - M'!$B:$B,"<="&EOMONTH('JN - Q'!$B7,0)) -> 82.279852 | J7: =AVERAGEIFS('JN - M'!K:K,'JN - M'!$B:$B,">="&EDATE('JN - Q'!$B7,-2),'JN - M'!$B:$B,"<="&EOMONTH('JN - Q'!$B7,0)) -> 2.1839602 | K7: =K8*S7/S8 -> 4.2171197 | L7: 0 | N7: =AVERAGEIFS('JN - M'!I:I,'JN - M'!$B:$B,">="&EDATE('JN - Q'!$B7,-2),'JN - M'!$B:$B,"<="&EOMONTH('JN - Q'!$B7,0)) -> 8.5153 | O7: =AVERAGEIFS('JN - M'!J:J,'JN - M'!$B:$B,">="&EDATE('JN - Q'!$B7,-2),'JN - M'!$B:$B,"<="&EOMONTH('JN - Q'!$B7,0)) -> 9.0195659 | S7: =(H7/H3-1)*100+2 -> 8.0028585
B8: 29738 | C8: ='CDM - Q'!M137 -> 293798.4 | G8: =AVERAGEIFS('JN - M'!D:D,'JN - M'!$B:$B,">="&EDATE('JN - Q'!$B8,-2),'JN - M'!$B:$B,"<="&EOMONTH('JN - Q'!$B8,0)) -> 83.564763 | H8: =AVERAGEIFS('JN - M'!E:E,'JN - M'!$B:$B,">="&EDATE('JN - Q'!$B8,-2),'JN - M'!$B:$B,"<="&EOMONTH('JN - Q'!$B8,0)) -> 83.759041 | I8: =AVERAGEIFS('JN - M'!F:F,'JN - M'!$B:$B,">="&EDATE('JN - Q'!$B8,-2),'JN - M'!$B:$B,"<="&EOMONTH('JN - Q'!$B8,0)) -> 83.759041 | J8: =AVERAGEIFS('JN - M'!K:K,'JN - M'!$B:$B,">="&EDATE('JN - Q'!$B8,-2),'JN - M'!$B:$B,"<="&EOMONTH('JN - Q'!$B8,0)) -> 2.2746378 | K8: =K9*S8/S9 -> 3.5643577 | L8: 0 | N8: =AVERAGEIFS('JN - M'!I:I,'JN - M'!$B:$B,">="&EDATE('JN - Q'!$B8,-2),'JN - M'!$B:$B,"<="&EOMONTH('JN - Q'!$B8,0)) -> 7.1200333 | O8: =AVERAGEIFS('JN - M'!J:J,'JN - M'!$B:$B,">="&EDATE('JN - Q'!$B8,-2),'JN - M'!$B:$B,"<="&EOMONTH('JN - Q'!$B8,0)) -> 7.5416732 | S8: =(H8/H4-1)*100+2 -> 6.7641073
B9: 29830 | C9: ='CDM - Q'!M138 -> 293144.94 | G9: =AVERAGEIFS('JN - M'!D:D,'JN - M'!$B:$B,">="&EDATE('JN - Q'!$B9,-2),'JN - M'!$B:$B,"<="&EOMONTH('JN - Q'!$B9,0)) -> 84.460922 | H9: =AVERAGEIFS('JN - M'!E:E,'JN - M'!$B:$B,">="&EDATE('JN - Q'!$B9,-2),'JN - M'!$B:$B,"<="&EOMONTH('JN - Q'!$B9,0)) -> 84.239777 | I9: =AVERAGEIFS('JN - M'!F:F,'JN - M'!$B:$B,">="&EDATE('JN - Q'!$B9,-2),'JN - M'!$B:$B,"<="&EOMONTH('JN - Q'!$B9,0)) -> 84.239777 | J9: =AVERAGEIFS('JN - M'!K:K,'JN - M'!$B:$B,">="&EDATE('JN - Q'!$B9,-2),'JN - M'!$B:$B,"<="&EOMONTH('JN - Q'!$B9,0)) -> 2.1598291 | K9: =K10*S9/S10 -> 3.2465235 | L9: 0 | N9: =AVERAGEIFS('JN - M'!I:I,'JN - M'!$B:$B,">="&EDATE('JN - Q'!$B9,-2),'JN - M'!$B:$B,"<="&EOMONTH('JN - Q'!$B9,0)) -> 7.2509 | O9: =AVERAGEIFS('JN - M'!J:J,'JN - M'!$B:$B,">="&EDATE('JN - Q'!$B9,-2),'JN - M'!$B:$B,"<="&EOMONTH('JN - Q'!$B9,0)) -> 7.6802896 | S9: =(H9/H5-1)*100+2 -> 6.1609511
B10: 29921 | C10: ='CDM - Q'!M139 -> 295284.72 | G10: =AVERAGEIFS('JN - M'!D:D,'JN - M'!$B:$B,">="&EDATE('JN - Q'!$B10,-2),'JN - M'!$B:$B,"<="&EOMONTH('JN - Q'!$B10,0)) -> 85.32145 | H10: =AVERAGEIFS('JN - M'!E:E,'JN - M'!$B:$B,">="&EDATE('JN - Q'!$B10,-2),'JN - M'!$B:$B,"<="&EOMONTH('JN - Q'!$B10,0)) -> 85.349168 | I10: =AVERAGEIFS('JN - M'!F:F,'JN - M'!$B:$B,">="&EDATE('JN - Q'!$B10,-2),'JN - M'!$B:$B,"<="&EOMONTH('JN - Q'!$B10,0)) -> 85.349168 | J10: =AVERAGEIFS('JN - M'!K:K,'JN - M'!$B:$B,">="&EDATE('JN - Q'!$B10,-2),'JN - M'!$B:$B,"<="&EOMONTH('JN - Q'!$B10,0)) -> 2.2174355 | K10: =K11*S10/S11 -> 3.1427208 | L10: 0 | N10: =AVERAGEIFS('JN - M'!I:I,'JN - M'!$B:$B,">="&EDATE('JN - Q'!$B10,-2),'JN - M'!$B:$B,"<="&EOMONTH('JN - Q'!$B10,0)) -> 6.8502667 | O10: =AVERAGEIFS('JN - M'!J:J,'JN - M'!$B:$B,">="&EDATE('JN - Q'!$B10,-2),'JN - M'!$B:$B,"<="&EOMONTH('JN - Q'!$B10,0)) -> 7.2559313 | S10: =(H10/H6-1)*100+2 -> 5.963964
A11: 1982 | B11: 30011 | C11: ='CDM - Q'!M140 -> 299809.96 | G11: =AVERAGEIFS('JN - M'!D:D,'JN - M'!$B:$B,">="&EDATE('JN - Q'!$B11,-2),'JN - M'!$B:$B,"<="&EOMONTH('JN - Q'!$B11,0)) -> 85.813063 | H11: =AVERAGEIFS('JN - M'!E:E,'JN - M'!$B:$B,">="&EDATE('JN - Q'!$B11,-2),'JN - M'!$B:$B,"<="&EOMONTH('JN - Q'!$B11,0)) -> 85.12729 | I11: =AVERAGEIFS('JN - M'!F:F,'JN - M'!$B:$B,">="&EDATE('JN - Q'!$B11,-2),'JN - M'!$B:$B,"<="&EOMONTH('JN - Q'!$B11,0)) -> 85.12729 | J11: =AVERAGEIFS('JN - M'!K:K,'JN - M'!$B:$B,">="&EDATE('JN - Q'!$B11,-2),'JN - M'!$B:$B,"<="&EOMONTH('JN - Q'!$B11,0)) -> 2.2333783 | K11: =K12*S11/S12 -> 2.8775114 | L11: 0 | N11: =AVERAGEIFS('JN - M'!I:I,'JN - M'!$B:$B,">="&EDATE('JN - Q'!$B11,-2),'JN - M'!$B:$B,"<="&EOMONTH('JN - Q'!$B11,0)) -> 6.6092333 | O11: =AVERAGEIFS('JN - M'!J:J,'JN - M'!$B:$B,">="&EDATE('JN - Q'!$B11,-2),'JN - M'!$B:$B,"<="&EOMONTH('JN - Q'!$B11,0)) -> 7.0006242 | S11: =(H11/H7-1)*100+2 -> 5.4606742
B12: 30103 | C12: ='CDM - Q'!M141 -> 301868.35 | G12: =AVERAGEIFS('JN - M'!D:D,'JN - M'!$B:$B,">="&EDATE('JN - Q'!$B12,-2),'JN - M'!$B:$B,"<="&EOMONTH('JN - Q'!$B12,0)) -> 86.22609 | H12: =AVERAGEIFS('JN - M'!E:E,'JN - M'!$B:$B,">="&EDATE('JN - Q'!$B12,-2),'JN - M'!$B:$B,"<="&EOMONTH('JN - Q'!$B12,0)) -> 86.310641 | I12: =AVERAGEIFS('JN - M'!F:F,'JN - M'!$B:$B,">="&EDATE('JN - Q'!$B12,-2),'JN - M'!$B:$B,"<="&EOMONTH('JN - Q'!$B12,0)) -> 86.310641 | J12: =AVERAGEIFS('JN - M'!K:K,'JN - M'!$B:$B,">="&EDATE('JN - Q'!$B12,-2),'JN - M'!$B:$B,"<="&EOMONTH('JN - Q'!$B12,0)) -> 2.3421579 | K12: =K13*S12/S13 -> 2.6591866 | L12: 0 | N12: =AVERAGEIFS('JN - M'!I:I,'JN - M'!$B:$B,">="&EDATE('JN - Q'!$B12,-2),'JN - M'!$B:$B,"<="&EOMONTH('JN - Q'!$B12,0)) -> 7.1722333 | O12: =AVERAGEIFS('JN - M'!J:J,'JN - M'!$B:$B,">="&EDATE('JN - Q'!$B12,-2),'JN - M'!$B:$B,"<="&EOMONTH('JN - Q'!$B12,0)) -> 7.5969644 | S12: =(H12/H8-1)*100+2 -> 5.0463576
B13: 30195 | C13: ='CDM - Q'!M142 -> 303187.53 | G13: =AVERAGEIFS('JN - M'!D:D,'JN - M'!$B:$B,">="&EDATE('JN - Q'!$B13,-2),'JN - M'!$B:$B,"<="&EOMONTH('JN - Q'!$B13,0)) -> 86.96563 | H13: =AVERAGEIFS('JN - M'!E:E,'JN - M'!$B:$B,">="&EDATE('JN - Q'!$B13,-2),'JN - M'!$B:$B,"<="&EOMONTH('JN - Q'!$B13,0)) -> 86.606478 | I13: =AVERAGEIFS('JN - M'!F:F,'JN - M'!$B:$B,">="&EDATE('JN - Q'!$B13,-2),'JN - M'!$B:$B,"<="&EOMONTH('JN - Q'!$B13,0)) -> 86.606478 | J13: =AVERAGEIFS('JN - M'!K:K,'JN - M'!$B:$B,">="&EDATE('JN - Q'!$B13,-2),'JN - M'!$B:$B,"<="&EOMONTH('JN - Q'!$B13,0)) -> 2.3711765 | K13: =K14*S13/S14 -> 2.5343646 | L13: 0 | N13: =AVERAGEIFS('JN - M'!I:I,'JN - M'!$B:$B,">="&EDATE('JN - Q'!$B13,-2),'JN - M'!$B:$B,"<="&EOMONTH('JN - Q'!$B13,0)) -> 7.1183 | O13: =AVERAGEIFS('JN - M'!J:J,'JN - M'!$B:$B,">="&EDATE('JN - Q'!$B13,-2),'JN - M'!$B:$B,"<="&EOMONTH('JN - Q'!$B13,0)) -> 7.5398372 | S13: =(H13/H9-1)*100+2 -> 4.809482
B14: 30286 | C14: ='CDM - Q'!M143 -> 307400.63 | G14: =AVERAGEIFS('JN - M'!D:D,'JN - M'!$B:$B,">="&EDATE('JN - Q'!$B14,-2),'JN - M'!$B:$B,"<="&EOMONTH('JN - Q'!$B14,0)) -> 87.572005 | H14: =AVERAGEIFS('JN - M'!E:E,'JN - M'!$B:$B,">="&EDATE('JN - Q'!$B14,-2),'JN - M'!$B:$B,"<="&EOMONTH('JN - Q'!$B14,0)) -> 87.567951 | I14: =AVERAGEIFS('JN - M'!F:F,'JN - M'!$B:$B,">="&EDATE('JN - Q'!$B14,-2),'JN - M'!$B:$B,"<="&EOMONTH('JN - Q'!$B14,0)) -> 87.567951 | J14: =AVERAGEIFS('JN - M'!K:K,'JN - M'!$B:$B,">="&EDATE('JN - Q'!$B14,-2),'JN - M'!$B:$B,"<="&EOMONTH('JN - Q'!$B14,0)) -> 2.4610027 | K14: =K15*S14/S15 -> 2.423795 | L14: 0 | N14: =AVERAGEIFS('JN - M'!I:I,'JN - M'!$B:$B,">="&EDATE('JN - Q'!$B14,-2),'JN - M'!$B:$B,"<="&EOMONTH('JN - Q'!$B14,0)) -> 6.8412333 | O14: =AVERAGEIFS('JN - M'!J:J,'JN - M'!$B:$B,">="&EDATE('JN - Q'!$B14,-2),'JN - M'!$B:$B,"<="&EOMONTH('JN - Q'!$B14,0)) -> 7.246363 | S14: =(H14/H10-1)*100+2 -> 4.5996534
A15: 1983 | B15: 30376 | C15: ='CDM - Q'!M144 -> 307594.48 | G15: =AVERAGEIFS('JN - M'!D:D,'JN - M'!$B:$B,">="&EDATE('JN - Q'!$B15,-2),'JN - M'!$B:$B,"<="&EOMONTH('JN - Q'!$B15,0)) -> 87.740424 | H15: =AVERAGEIFS('JN - M'!E:E,'JN - M'!$B:$B,">="&EDATE('JN - Q'!$B15,-2),'JN - M'!$B:$B,"<="&EOMONTH('JN - Q'!$B15,0)) -> 87.124194 | I15: =AVERAGEIFS('JN - M'!F:F,'JN - M'!$B:$B,">="&EDATE('JN - Q'!$B15,-2),'JN - M'!$B:$B,"<="&EOMONTH('JN - Q'!$B15,0)) -> 87.124194 | J15: =AVERAGEIFS('JN - M'!K:K,'JN - M'!$B:$B,">="&EDATE('JN - Q'!$B15,-2),'JN - M'!$B:$B,"<="&EOMONTH('JN - Q'!$B15,0)) -> 2.6717197 | K15: =K16*S15/S16 -> 2.2900193 | L15: 0 | N15: =AVERAGEIFS('JN - M'!I:I,'JN - M'!$B:$B,">="&EDATE('JN - Q'!$B15,-2),'JN - M'!$B:$B,"<="&EOMONTH('JN - Q'!$B15,0)) -> 6.6356667 | O15: =AVERAGEIFS('JN - M'!J:J,'JN - M'!$B:$B,">="&EDATE('JN - Q'!$B15,-2),'JN - M'!$B:$B,"<="&EOMONTH('JN - Q'!$B15,0)) -> 7.0286229 | S15: =(H15/H11-1)*100+2 -> 4.3457863
B16: 30468 | C16: ='CDM - Q'!M145 -> 309907.44 | G16: =AVERAGEIFS('JN - M'!D:D,'JN - M'!$B:$B,">="&EDATE('JN - Q'!$B16,-2),'JN - M'!$B:$B,"<="&EOMONTH('JN - Q'!$B16,0)) -> 87.943773 | H16: =AVERAGEIFS('JN - M'!E:E,'JN - M'!$B:$B,">="&EDATE('JN - Q'!$B16,-2),'JN - M'!$B:$B,"<="&EOMONTH('JN - Q'!$B16,0)) -> 88.344525 | I16: =AVERAGEIFS('JN - M'!F:F,'JN - M'!$B:$B,">="&EDATE('JN - Q'!$B16,-2),'JN - M'!$B:$B,"<="&EOMONTH('JN - Q'!$B16,0)) -> 88.344525 | J16: =AVERAGEIFS('JN - M'!K:K,'JN - M'!$B:$B,">="&EDATE('JN - Q'!$B16,-2),'JN - M'!$B:$B,"<="&EOMONTH('JN - Q'!$B16,0)) -> 2.6450835 | K16: =K17*S16/S17 -> 2.2956489 | L16: 0 | N16: =AVERAGEIFS('JN - M'!I:I,'JN - M'!$B:$B,">="&EDATE('JN - Q'!$B16,-2),'JN - M'!$B:$B,"<="&EOMONTH('JN - Q'!$B16,0)) -> 6.1909333 | O16: =AVERAGEIFS('JN - M'!J:J,'JN - M'!$B:$B,">="&EDATE('JN - Q'!$B16,-2),'JN - M'!$B:$B,"<="&EOMONTH('JN - Q'!$B16,0)) -> 6.557553 | S16: =(H16/H12-1)*100+2 -> 4.3564696
B17: 30560 | C17: ='CDM - Q'!M146 -> 314544.44 | G17: =AVERAGEIFS('JN - M'!D:D,'JN - M'!$B:$B,">="&EDATE('JN - Q'!$B17,-2),'JN - M'!$B:$B,"<="&EOMONTH('JN - Q'!$B17,0)) -> 88.30048 | H17: =AVERAGEIFS('JN - M'!E:E,'JN - M'!$B:$B,">="&EDATE('JN - Q'!$B17,-2),'JN - M'!$B:$B,"<="&EOMONTH('JN - Q'!$B17,0)) -> 88.455464 | I17: =AVERAGEIFS('JN - M'!F:F,'JN - M'!$B:$B,">="&EDATE('JN - Q'!$B17,-2),'JN - M'!$B:$B,"<="&EOMONTH('JN - Q'!$B17,0)) -> 88.455464 | J17: =AVERAGEIFS('JN - M'!K:K,'JN - M'!$B:$B,">="&EDATE('JN - Q'!$B17,-2),'JN - M'!$B:$B,"<="&EOMONTH('JN - Q'!$B17,0)) -> 2.6748134 | K17: =K18*S17/S18 -> 2.1789069 | L17: 0 | N17: =AVERAGEIFS('JN - M'!I:I,'JN - M'!$B:$B,">="&EDATE('JN - Q'!$B17,-2),'JN - M'!$B:$B,"<="&EOMONTH('JN - Q'!$B17,0)) -> 6.4587667 | O17: =AVERAGEIFS('JN - M'!J:J,'JN - M'!$B:$B,">="&EDATE('JN - Q'!$B17,-2),'JN - M'!$B:$B,"<="&EOMONTH('JN - Q'!$B17,0)) -> 6.8412471 | S17: =(H17/H13-1)*100+2 -> 4.1349274
B18: 30651 | C18: ='CDM - Q'!M147 -> 317164.99 | G18: =AVERAGEIFS('JN - M'!D:D,'JN - M'!$B:$B,">="&EDATE('JN - Q'!$B18,-2),'JN - M'!$B:$B,"<="&EOMONTH('JN - Q'!$B18,0)) -> 89.007704 | H18: =AVERAGEIFS('JN - M'!E:E,'JN - M'!$B:$B,">="&EDATE('JN - Q'!$B18,-2),'JN - M'!$B:$B,"<="&EOMONTH('JN - Q'!$B18,0)) -> 89.527875 | I18: =AVERAGEIFS('JN - M'!F:F,'JN - M'!$B:$B,">="&EDATE('JN - Q'!$B18,-2),'JN - M'!$B:$B,"<="&EOMONTH('JN - Q'!$B18,0)) -> 89.527875 | J18: =AVERAGEIFS('JN - M'!K:K,'JN - M'!$B:$B,">="&EDATE('JN - Q'!$B18,-2),'JN - M'!$B:$B,"<="&EOMONTH('JN - Q'!$B18,0)) -> 2.621624 | K18: =K19*S18/S19 -> 2.2333138 | L18: 0 | N18: =AVERAGEIFS('JN - M'!I:I,'JN - M'!$B:$B,">="&EDATE('JN - Q'!$B18,-2),'JN - M'!$B:$B,"<="&EOMONTH('JN - Q'!$B18,0)) -> 6.2836667 | O18: =AVERAGEIFS('JN - M'!J:J,'JN - M'!$B:$B,">="&EDATE('JN - Q'!$B18,-2),'JN - M'!$B:$B,"<="&EOMONTH('JN - Q'!$B18,0)) -> 6.6557779 | S18: =(H18/H14-1)*100+2 -> 4.2381757
A19: 1984 | B19: 30742 | C19: ='CDM - Q'!M148 -> 320817.71 | G19: =AVERAGEIFS('JN - M'!D:D,'JN - M'!$B:$B,">="&EDATE('JN - Q'!$B19,-2),'JN - M'!$B:$B,"<="&EOMONTH('JN - Q'!$B19,0)) -> 89.334208 | H19: =AVERAGEIFS('JN - M'!E:E,'JN - M'!$B:$B,">="&EDATE('JN - Q'!$B19,-2),'JN - M'!$B:$B,"<="&EOMONTH('JN - Q'!$B19,0)) -> 89.305997 | I19: =AVERAGEIFS('JN - M'!F:F,'JN - M'!$B:$B,">="&EDATE('JN - Q'!$B19,-2),'JN - M'!$B:$B,"<="&EOMONTH('JN - Q'!$B19,0)) -> 89.305997 | J19: =AVERAGEIFS('JN - M'!K:K,'JN - M'!$B:$B,">="&EDATE('JN - Q'!$B19,-2),'JN - M'!$B:$B,"<="&EOMONTH('JN - Q'!$B19,0)) -> 2.7405279 | K19: =K20*S19/S20 -> 2.3735192 | L19: 0 | N19: =AVERAGEIFS('JN - M'!I:I,'JN - M'!$B:$B,">="&EDATE('JN - Q'!$B19,-2),'JN - M'!$B:$B,"<="&EOMONTH('JN - Q'!$B19,0)) -> 6.1817667 | O19: =AVERAGEIFS('JN - M'!J:J,'JN - M'!$B:$B,">="&EDATE('JN - Q'!$B19,-2),'JN - M'!$B:$B,"<="&EOMONTH('JN - Q'!$B19,0)) -> 6.5478435 | S19: =(H19/H15-1)*100+2 -> 4.5042445
B20: 30834 | C20: ='CDM - Q'!M149 -> 325676.25 | G20: =AVERAGEIFS('JN - M'!D:D,'JN - M'!$B:$B,">="&EDATE('JN - Q'!$B20,-2),'JN - M'!$B:$B,"<="&EOMONTH('JN - Q'!$B20,0)) -> 89.833273 | H20: =AVERAGEIFS('JN - M'!E:E,'JN - M'!$B:$B,">="&EDATE('JN - Q'!$B20,-2),'JN - M'!$B:$B,"<="&EOMONTH('JN - Q'!$B20,0)) -> 90.526327 | I20: =AVERAGEIFS('JN - M'!F:F,'JN - M'!$B:$B,">="&EDATE('JN - Q'!$B20,-2),'JN - M'!$B:$B,"<="&EOMONTH('JN - Q'!$B20,0)) -> 90.526327 | J20: =AVERAGEIFS('JN - M'!K:K,'JN - M'!$B:$B,">="&EDATE('JN - Q'!$B20,-2),'JN - M'!$B:$B,"<="&EOMONTH('JN - Q'!$B20,0)) -> 2.7143292 | K20: =K21*S20/S21 -> 2.3552909 | L20: 0 | N20: =AVERAGEIFS('JN - M'!I:I,'JN - M'!$B:$B,">="&EDATE('JN - Q'!$B20,-2),'JN - M'!$B:$B,"<="&EOMONTH('JN - Q'!$B20,0)) -> 5.8443 | O20: =AVERAGEIFS('JN - M'!J:J,'JN - M'!$B:$B,">="&EDATE('JN - Q'!$B20,-2),'JN - M'!$B:$B,"<="&EOMONTH('JN - Q'!$B20,0)) -> 6.1903925 | S20: =(H20/H16-1)*100+2 -> 4.4696526
B21: 30926 | C21: ='CDM - Q'!M150 -> 329656.23 | G21: =AVERAGEIFS('JN - M'!D:D,'JN - M'!$B:$B,">="&EDATE('JN - Q'!$B21,-2),'JN - M'!$B:$B,"<="&EOMONTH('JN - Q'!$B21,0)) -> 90.242485 | H21: =AVERAGEIFS('JN - M'!E:E,'JN - M'!$B:$B,">="&EDATE('JN - Q'!$B21,-2),'JN - M'!$B:$B,"<="&EOMONTH('JN - Q'!$B21,0)) -> 90.637267 | I21: =AVERAGEIFS('JN - M'!F:F,'JN - M'!$B:$B,">="&EDATE('JN - Q'!$B21,-2),'JN - M'!$B:$B,"<="&EOMONTH('JN - Q'!$B21,0)) -> 90.637267 | J21: =AVERAGEIFS('JN - M'!K:K,'JN - M'!$B:$B,">="&EDATE('JN - Q'!$B21,-2),'JN - M'!$B:$B,"<="&EOMONTH('JN - Q'!$B21,0)) -> 2.7312395 | K21: =K22*S21/S22 -> 2.3536587 | L21: 0 | N21: =AVERAGEIFS('JN - M'!I:I,'JN - M'!$B:$B,">="&EDATE('JN - Q'!$B21,-2),'JN - M'!$B:$B,"<="&EOMONTH('JN - Q'!$B21,0)) -> 6.1527667 | O21: =AVERAGEIFS('JN - M'!J:J,'JN - M'!$B:$B,">="&EDATE('JN - Q'!$B21,-2),'JN - M'!$B:$B,"<="&EOMONTH('JN - Q'!$B21,0)) -> 6.5171262 | S21: =(H21/H17-1)*100+2 -> 4.4665552
B22: 31017 | C22: ='CDM - Q'!M151 -> 330225.23 | G22: =AVERAGEIFS('JN - M'!D:D,'JN - M'!$B:$B,">="&EDATE('JN - Q'!$B22,-2),'JN - M'!$B:$B,"<="&EOMONTH('JN - Q'!$B22,0)) -> 91.046593 | H22: =AVERAGEIFS('JN - M'!E:E,'JN - M'!$B:$B,">="&EDATE('JN - Q'!$B22,-2),'JN - M'!$B:$B,"<="&EOMONTH('JN - Q'!$B22,0)) -> 91.820617 | I22: =AVERAGEIFS('JN - M'!F:F,'JN - M'!$B:$B,">="&EDATE('JN - Q'!$B22,-2),'JN - M'!$B:$B,"<="&EOMONTH('JN - Q'!$B22,0)) -> 91.820617 | J22: =AVERAGEIFS('JN - M'!K:K,'JN - M'!$B:$B,">="&EDATE('JN - Q'!$B22,-2),'JN - M'!$B:$B,"<="&EOMONTH('JN - Q'!$B22,0)) -> 2.6796846 | K22: =K23*S22/S23 -> 2.4033872 | L22: 0 | N22: =AVERAGEIFS('JN - M'!I:I,'JN - M'!$B:$B,">="&EDATE('JN - Q'!$B22,-2),'JN - M'!$B:$B,"<="&EOMONTH('JN - Q'!$B22,0)) -> 6.2211 | O22: =AVERAGEIFS('JN - M'!J:J,'JN - M'!$B:$B,">="&EDATE('JN - Q'!$B22,-2),'JN - M'!$B:$B,"<="&EOMONTH('JN - Q'!$B22,0)) -> 6.5895061 | S22: =(H22/H18-1)*100+2 -> 4.5609252
A23: 1985 | B23: 31107 | C23: ='CDM - Q'!M152 -> 338317.63 | G23: =AVERAGEIFS('JN - M'!D:D,'JN - M'!$B:$B,">="&EDATE('JN - Q'!$B23,-2),'JN - M'!$B:$B,"<="&EOMONTH('JN - Q'!$B23,0)) -> 91.480649 | H23: =AVERAGEIFS('JN - M'!E:E,'JN - M'!$B:$B,">="&EDATE('JN - Q'!$B23,-2),'JN - M'!$B:$B,"<="&EOMONTH('JN - Q'!$B23,0)) -> 91.746658 | I23: =AVERAGEIFS('JN - M'!F:F,'JN - M'!$B:$B,">="&EDATE('JN - Q'!$B23,-2),'JN - M'!$B:$B,"<="&EOMONTH('JN - Q'!$B23,0)) -> 91.746658 | J23: =AVERAGEIFS('JN - M'!K:K,'JN - M'!$B:$B,">="&EDATE('JN - Q'!$B23,-2),'JN - M'!$B:$B,"<="&EOMONTH('JN - Q'!$B23,0)) -> 2.5623958 | K23: =K24*S23/S24 -> 2.4940197 | L23: 0 | N23: =AVERAGEIFS('JN - M'!I:I,'JN - M'!$B:$B,">="&EDATE('JN - Q'!$B23,-2),'JN - M'!$B:$B,"<="&EOMONTH('JN - Q'!$B23,0)) -> 6.2487333 | O23: =AVERAGEIFS('JN - M'!J:J,'JN - M'!$B:$B,">="&EDATE('JN - Q'!$B23,-2),'JN - M'!$B:$B,"<="&EOMONTH('JN - Q'!$B23,0)) -> 6.6187759 | S23: =(H23/H19-1)*100+2 -> 4.7329193
B24: 31199 | C24: ='CDM - Q'!M153 -> 345168.39 | G24: =AVERAGEIFS('JN - M'!D:D,'JN - M'!$B:$B,">="&EDATE('JN - Q'!$B24,-2),'JN - M'!$B:$B,"<="&EOMONTH('JN - Q'!$B24,0)) -> 91.813508 | H24: =AVERAGEIFS('JN - M'!E:E,'JN - M'!$B:$B,">="&EDATE('JN - Q'!$B24,-2),'JN - M'!$B:$B,"<="&EOMONTH('JN - Q'!$B24,0)) -> 92.671151 | I24: =AVERAGEIFS('JN - M'!F:F,'JN - M'!$B:$B,">="&EDATE('JN - Q'!$B24,-2),'JN - M'!$B:$B,"<="&EOMONTH('JN - Q'!$B24,0)) -> 92.671151 | J24: =AVERAGEIFS('JN - M'!K:K,'JN - M'!$B:$B,">="&EDATE('JN - Q'!$B24,-2),'JN - M'!$B:$B,"<="&EOMONTH('JN - Q'!$B24,0)) -> 2.5467524 | K24: =K25*S24/S25 -> 2.3024 | L24: 0 | N24: =AVERAGEIFS('JN - M'!I:I,'JN - M'!$B:$B,">="&EDATE('JN - Q'!$B24,-2),'JN - M'!$B:$B,"<="&EOMONTH('JN - Q'!$B24,0)) -> 6.0685667 | O24: =AVERAGEIFS('JN - M'!J:J,'JN - M'!$B:$B,">="&EDATE('JN - Q'!$B24,-2),'JN - M'!$B:$B,"<="&EOMONTH('JN - Q'!$B24,0)) -> 6.4279399 | S24: =(H24/H20-1)*100+2 -> 4.369281
B25: 31291 | C25: ='CDM - Q'!M154 -> 349685.13 | G25: =AVERAGEIFS('JN - M'!D:D,'JN - M'!$B:$B,">="&EDATE('JN - Q'!$B25,-2),'JN - M'!$B:$B,"<="&EOMONTH('JN - Q'!$B25,0)) -> 92.110872 | H25: =AVERAGEIFS('JN - M'!E:E,'JN - M'!$B:$B,">="&EDATE('JN - Q'!$B25,-2),'JN - M'!$B:$B,"<="&EOMONTH('JN - Q'!$B25,0)) -> 92.819069 | I25: =AVERAGEIFS('JN - M'!F:F,'JN - M'!$B:$B,">="&EDATE('JN - Q'!$B25,-2),'JN - M'!$B:$B,"<="&EOMONTH('JN - Q'!$B25,0)) -> 92.819069 | J25: =AVERAGEIFS('JN - M'!K:K,'JN - M'!$B:$B,">="&EDATE('JN - Q'!$B25,-2),'JN - M'!$B:$B,"<="&EOMONTH('JN - Q'!$B25,0)) -> 2.5862001 | K25: =K26*S25/S26 -> 2.3223713 | L25: 0 | N25: =AVERAGEIFS('JN - M'!I:I,'JN - M'!$B:$B,">="&EDATE('JN - Q'!$B25,-2),'JN - M'!$B:$B,"<="&EOMONTH('JN - Q'!$B25,0)) -> 6.2540333 | O25: =AVERAGEIFS('JN - M'!J:J,'JN - M'!$B:$B,">="&EDATE('JN - Q'!$B25,-2),'JN - M'!$B:$B,"<="&EOMONTH('JN - Q'!$B25,0)) -> 6.6243897 | S25: =(H25/H21-1)*100+2 -> 4.4071807
B26: 31382 | C26: ='CDM - Q'!M155 -> 354330.43 | G26: =AVERAGEIFS('JN - M'!D:D,'JN - M'!$B:$B,">="&EDATE('JN - Q'!$B26,-2),'JN - M'!$B:$B,"<="&EOMONTH('JN - Q'!$B26,0)) -> 92.297282 | H26: =AVERAGEIFS('JN - M'!E:E,'JN - M'!$B:$B,">="&EDATE('JN - Q'!$B26,-2),'JN - M'!$B:$B,"<="&EOMONTH('JN - Q'!$B26,0)) -> 93.410745 | I26: =AVERAGEIFS('JN - M'!F:F,'JN - M'!$B:$B,">="&EDATE('JN - Q'!$B26,-2),'JN - M'!$B:$B,"<="&EOMONTH('JN - Q'!$B26,0)) -> 93.410745 | J26: =AVERAGEIFS('JN - M'!K:K,'JN - M'!$B:$B,">="&EDATE('JN - Q'!$B26,-2),'JN - M'!$B:$B,"<="&EOMONTH('JN - Q'!$B26,0)) -> 2.7792051 | K26: =K27*S26/S27 -> 1.9664656 | L26: 0 | N26: =AVERAGEIFS('JN - M'!I:I,'JN - M'!$B:$B,">="&EDATE('JN - Q'!$B26,-2),'JN - M'!$B:$B,"<="&EOMONTH('JN - Q'!$B26,0)) -> 7.2818333 | O26: =AVERAGEIFS('JN - M'!J:J,'JN - M'!$B:$B,">="&EDATE('JN - Q'!$B26,-2),'JN - M'!$B:$B,"<="&EOMONTH('JN - Q'!$B26,0)) -> 7.7130548 | S26: =(H26/H22-1)*100+2 -> 3.7317761
A27: 1986 | B27: 31472 | C27: ='CDM - Q'!M156 -> 355739.42 | G27: =AVERAGEIFS('JN - M'!D:D,'JN - M'!$B:$B,">="&EDATE('JN - Q'!$B27,-2),'JN - M'!$B:$B,"<="&EOMONTH('JN - Q'!$B27,0)) -> 92.755167 | H27: =AVERAGEIFS('JN - M'!E:E,'JN - M'!$B:$B,">="&EDATE('JN - Q'!$B27,-2),'JN - M'!$B:$B,"<="&EOMONTH('JN - Q'!$B27,0)) -> 93.336785 | I27: =AVERAGEIFS('JN - M'!F:F,'JN - M'!$B:$B,">="&EDATE('JN - Q'!$B27,-2),'JN - M'!$B:$B,"<="&EOMONTH('JN - Q'!$B27,0)) -> 93.336785 | J27: =AVERAGEIFS('JN - M'!K:K,'JN - M'!$B:$B,">="&EDATE('JN - Q'!$B27,-2),'JN - M'!$B:$B,"<="&EOMONTH('JN - Q'!$B27,0)) -> 2.6757036 | K27: =K28*S27/S28 -> 1.9672013 | L27: 0 | N27: =AVERAGEIFS('JN - M'!I:I,'JN - M'!$B:$B,">="&EDATE('JN - Q'!$B27,-2),'JN - M'!$B:$B,"<="&EOMONTH('JN - Q'!$B27,0)) -> 6.053 | O27: =AVERAGEIFS('JN - M'!J:J,'JN - M'!$B:$B,">="&EDATE('JN - Q'!$B27,-2),'JN - M'!$B:$B,"<="&EOMONTH('JN - Q'!$B27,0)) -> 6.4114514 | S27: =(H27/H23-1)*100+2 -> 3.7331721
B28: 31564 | C28: ='CDM - Q'!M157 -> 354865.4 | G28: =AVERAGEIFS('JN - M'!D:D,'JN - M'!$B:$B,">="&EDATE('JN - Q'!$B28,-2),'JN - M'!$B:$B,"<="&EOMONTH('JN - Q'!$B28,0)) -> 92.843616 | H28: =AVERAGEIFS('JN - M'!E:E,'JN - M'!$B:$B,">="&EDATE('JN - Q'!$B28,-2),'JN - M'!$B:$B,"<="&EOMONTH('JN - Q'!$B28,0)) -> 94.224298 | I28: =AVERAGEIFS('JN - M'!F:F,'JN - M'!$B:$B,">="&EDATE('JN - Q'!$B28,-2),'JN - M'!$B:$B,"<="&EOMONTH('JN - Q'!$B28,0)) -> 94.224298 | J28: =AVERAGEIFS('JN - M'!K:K,'JN - M'!$B:$B,">="&EDATE('JN - Q'!$B28,-2),'JN - M'!$B:$B,"<="&EOMONTH('JN - Q'!$B28,0)) -> 2.7539109 | K28: =K29*S28/S29 -> 1.9370626 | L28: 0 | N28: =AVERAGEIFS('JN - M'!I:I,'JN - M'!$B:$B,">="&EDATE('JN - Q'!$B28,-2),'JN - M'!$B:$B,"<="&EOMONTH('JN - Q'!$B28,0)) -> 4.4357333 | O28: =AVERAGEIFS('JN - M'!J:J,'JN - M'!$B:$B,">="&EDATE('JN - Q'!$B28,-2),'JN - M'!$B:$B,"<="&EOMONTH('JN - Q'!$B28,0)) -> 4.6984122 | S28: =(H28/H24-1)*100+2 -> 3.6759777
B29: 31656 | C29: ='CDM - Q'!M158 -> 356944.16 | G29: =AVERAGEIFS('JN - M'!D:D,'JN - M'!$B:$B,">="&EDATE('JN - Q'!$B29,-2),'JN - M'!$B:$B,"<="&EOMONTH('JN - Q'!$B29,0)) -> 92.623869 | H29: =AVERAGEIFS('JN - M'!E:E,'JN - M'!$B:$B,">="&EDATE('JN - Q'!$B29,-2),'JN - M'!$B:$B,"<="&EOMONTH('JN - Q'!$B29,0)) -> 94.224298 | I29: =AVERAGEIFS('JN - M'!F:F,'JN - M'!$B:$B,">="&EDATE('JN - Q'!$B29,-2),'JN - M'!$B:$B,"<="&EOMONTH('JN - Q'!$B29,0)) -> 94.224298 | J29: =AVERAGEIFS('JN - M'!K:K,'JN - M'!$B:$B,">="&EDATE('JN - Q'!$B29,-2),'JN - M'!$B:$B,"<="&EOMONTH('JN - Q'!$B29,0)) -> 2.8438701 | K29: =K30*S29/S30 -> 1.8516788 | L29: 0 | N29: =AVERAGEIFS('JN - M'!I:I,'JN - M'!$B:$B,">="&EDATE('JN - Q'!$B29,-2),'JN - M'!$B:$B,"<="&EOMONTH('JN - Q'!$B29,0)) -> 4.5625333 | O29: =AVERAGEIFS('JN - M'!J:J,'JN - M'!$B:$B,">="&EDATE('JN - Q'!$B29,-2),'JN - M'!$B:$B,"<="&EOMONTH('JN - Q'!$B29,0)) -> 4.8327211 | S29: =(H29/H25-1)*100+2 -> 3.5139442
B30: 31747 | C30: ='CDM - Q'!M159 -> 359759.46 | G30: =AVERAGEIFS('JN - M'!D:D,'JN - M'!$B:$B,">="&EDATE('JN - Q'!$B30,-2),'JN - M'!$B:$B,"<="&EOMONTH('JN - Q'!$B30,0)) -> 92.569319 | H30: =AVERAGEIFS('JN - M'!E:E,'JN - M'!$B:$B,">="&EDATE('JN - Q'!$B30,-2),'JN - M'!$B:$B,"<="&EOMONTH('JN - Q'!$B30,0)) -> 94.778994 | I30: =AVERAGEIFS('JN - M'!F:F,'JN - M'!$B:$B,">="&EDATE('JN - Q'!$B30,-2),'JN - M'!$B:$B,"<="&EOMONTH('JN - Q'!$B30,0)) -> 94.778994 | J30: =AVERAGEIFS('JN - M'!K:K,'JN - M'!$B:$B,">="&EDATE('JN - Q'!$B30,-2),'JN - M'!$B:$B,"<="&EOMONTH('JN - Q'!$B30,0)) -> 2.7941754 | K30: =K31*S30/S31 -> 1.8257645 | L30: 0 | N30: =AVERAGEIFS('JN - M'!I:I,'JN - M'!$B:$B,">="&EDATE('JN - Q'!$B30,-2),'JN - M'!$B:$B,"<="&EOMONTH('JN - Q'!$B30,0)) -> 4.1207333 | O30: =AVERAGEIFS('JN - M'!J:J,'JN - M'!$B:$B,">="&EDATE('JN - Q'!$B30,-2),'JN - M'!$B:$B,"<="&EOMONTH('JN - Q'!$B30,0)) -> 4.3647582 | S30: =(H30/H26-1)*100+2 -> 3.4647664
A31: 1987 | B31: 31837 | C31: ='CDM - Q'!M160 -> 359501.42 | G31: =AVERAGEIFS('JN - M'!D:D,'JN - M'!$B:$B,">="&EDATE('JN - Q'!$B31,-2),'JN - M'!$B:$B,"<="&EOMONTH('JN - Q'!$B31,0)) -> 92.616929 | H31: =AVERAGEIFS('JN - M'!E:E,'JN - M'!$B:$B,">="&EDATE('JN - Q'!$B31,-2),'JN - M'!$B:$B,"<="&EOMONTH('JN - Q'!$B31,0)) -> 94.446177 | I31: =AVERAGEIFS('JN - M'!F:F,'JN - M'!$B:$B,">="&EDATE('JN - Q'!$B31,-2),'JN - M'!$B:$B,"<="&EOMONTH('JN - Q'!$B31,0)) -> 94.446177 | J31: =AVERAGEIFS('JN - M'!K:K,'JN - M'!$B:$B,">="&EDATE('JN - Q'!$B31,-2),'JN - M'!$B:$B,"<="&EOMONTH('JN - Q'!$B31,0)) -> 2.9426737 | K31: =K32*S31/S32 -> 1.6802326 | L31: 0 | N31: =AVERAGEIFS('JN - M'!I:I,'JN - M'!$B:$B,">="&EDATE('JN - Q'!$B31,-2),'JN - M'!$B:$B,"<="&EOMONTH('JN - Q'!$B31,0)) -> 3.9980333 | O31: =AVERAGEIFS('JN - M'!J:J,'JN - M'!$B:$B,">="&EDATE('JN - Q'!$B31,-2),'JN - M'!$B:$B,"<="&EOMONTH('JN - Q'!$B31,0)) -> 4.2347921 | S31: =(H31/H27-1)*100+2 -> 3.1885895
B32: 31929 | C32: ='CDM - Q'!M161 -> 367035.11 | G32: =AVERAGEIFS('JN - M'!D:D,'JN - M'!$B:$B,">="&EDATE('JN - Q'!$B32,-2),'JN - M'!$B:$B,"<="&EOMONTH('JN - Q'!$B32,0)) -> 92.88688 | H32: =AVERAGEIFS('JN - M'!E:E,'JN - M'!$B:$B,">="&EDATE('JN - Q'!$B32,-2),'JN - M'!$B:$B,"<="&EOMONTH('JN - Q'!$B32,0)) -> 95.037852 | I32: =AVERAGEIFS('JN - M'!F:F,'JN - M'!$B:$B,">="&EDATE('JN - Q'!$B32,-2),'JN - M'!$B:$B,"<="&EOMONTH('JN - Q'!$B32,0)) -> 95.037852 | J32: =AVERAGEIFS('JN - M'!K:K,'JN - M'!$B:$B,">="&EDATE('JN - Q'!$B32,-2),'JN - M'!$B:$B,"<="&EOMONTH('JN - Q'!$B32,0)) -> 3.0070389 | K32: =K33*S32/S33 -> 1.5088852 | L32: 0 | N32: =AVERAGEIFS('JN - M'!I:I,'JN - M'!$B:$B,">="&EDATE('JN - Q'!$B32,-2),'JN - M'!$B:$B,"<="&EOMONTH('JN - Q'!$B32,0)) -> 3.2817667 | O32: =AVERAGEIFS('JN - M'!J:J,'JN - M'!$B:$B,">="&EDATE('JN - Q'!$B32,-2),'JN - M'!$B:$B,"<="&EOMONTH('JN - Q'!$B32,0)) -> 3.476109 | S32: =(H32/H28-1)*100+2 -> 2.8634223
B33: 32021 | C33: ='CDM - Q'!M162 -> 374376.83 | G33: =AVERAGEIFS('JN - M'!D:D,'JN - M'!$B:$B,">="&EDATE('JN - Q'!$B33,-2),'JN - M'!$B:$B,"<="&EOMONTH('JN - Q'!$B33,0)) -> 93.103929 | H33: =AVERAGEIFS('JN - M'!E:E,'JN - M'!$B:$B,">="&EDATE('JN - Q'!$B33,-2),'JN - M'!$B:$B,"<="&EOMONTH('JN - Q'!$B33,0)) -> 95.074832 | I33: =AVERAGEIFS('JN - M'!F:F,'JN - M'!$B:$B,">="&EDATE('JN - Q'!$B33,-2),'JN - M'!$B:$B,"<="&EOMONTH('JN - Q'!$B33,0)) -> 95.074832 | J33: =AVERAGEIFS('JN - M'!K:K,'JN - M'!$B:$B,">="&EDATE('JN - Q'!$B33,-2),'JN - M'!$B:$B,"<="&EOMONTH('JN - Q'!$B33,0)) -> 2.7532668 | K33: =K34*S33/S34 -> 1.5295662 | L33: 0 | N33: =AVERAGEIFS('JN - M'!I:I,'JN - M'!$B:$B,">="&EDATE('JN - Q'!$B33,-2),'JN - M'!$B:$B,"<="&EOMONTH('JN - Q'!$B33,0)) -> 3.2489333 | O33: =AVERAGEIFS('JN - M'!J:J,'JN - M'!$B:$B,">="&EDATE('JN - Q'!$B33,-2),'JN - M'!$B:$B,"<="&EOMONTH('JN - Q'!$B33,0)) -> 3.4413313 | S33: =(H33/H29-1)*100+2 -> 2.9026688
B34: 32112 | C34: ='CDM - Q'!M163 -> 384016.28 | G34: =AVERAGEIFS('JN - M'!D:D,'JN - M'!$B:$B,">="&EDATE('JN - Q'!$B34,-2),'JN - M'!$B:$B,"<="&EOMONTH('JN - Q'!$B34,0)) -> 93.081721 | H34: =AVERAGEIFS('JN - M'!E:E,'JN - M'!$B:$B,">="&EDATE('JN - Q'!$B34,-2),'JN - M'!$B:$B,"<="&EOMONTH('JN - Q'!$B34,0)) -> 95.444629 | I34: =AVERAGEIFS('JN - M'!F:F,'JN - M'!$B:$B,">="&EDATE('JN - Q'!$B34,-2),'JN - M'!$B:$B,"<="&EOMONTH('JN - Q'!$B34,0)) -> 95.444629 | J34: =AVERAGEIFS('JN - M'!K:K,'JN - M'!$B:$B,">="&EDATE('JN - Q'!$B34,-2),'JN - M'!$B:$B,"<="&EOMONTH('JN - Q'!$B34,0)) -> 2.6737895 | K34: =K35*S34/S35 -> 1.4239826 | L34: 0 | N34: =AVERAGEIFS('JN - M'!I:I,'JN - M'!$B:$B,">="&EDATE('JN - Q'!$B34,-2),'JN - M'!$B:$B,"<="&EOMONTH('JN - Q'!$B34,0)) -> 3.5249667 | O34: =AVERAGEIFS('JN - M'!J:J,'JN - M'!$B:$B,">="&EDATE('JN - Q'!$B34,-2),'JN - M'!$B:$B,"<="&EOMONTH('JN - Q'!$B34,0)) -> 3.733711 | S34: =(H34/H30-1)*100+2 -> 2.702302
A35: 1988 | B35: 32203 | C35: ='CDM - Q'!M164 -> 393183.57 | G35: =AVERAGEIFS('JN - M'!D:D,'JN - M'!$B:$B,">="&EDATE('JN - Q'!$B35,-2),'JN - M'!$B:$B,"<="&EOMONTH('JN - Q'!$B35,0)) -> 93.11523 | H35: =AVERAGEIFS('JN - M'!E:E,'JN - M'!$B:$B,">="&EDATE('JN - Q'!$B35,-2),'JN - M'!$B:$B,"<="&EOMONTH('JN - Q'!$B35,0)) -> 95.037852 | I35: =AVERAGEIFS('JN - M'!F:F,'JN - M'!$B:$B,">="&EDATE('JN - Q'!$B35,-2),'JN - M'!$B:$B,"<="&EOMONTH('JN - Q'!$B35,0)) -> 95.037852 | J35: =AVERAGEIFS('JN - M'!K:K,'JN - M'!$B:$B,">="&EDATE('JN - Q'!$B35,-2),'JN - M'!$B:$B,"<="&EOMONTH('JN - Q'!$B35,0)) -> 2.6941991 | K35: =K36*S35/S36 -> 1.3840219 | L35: 0 | N35: =AVERAGEIFS('JN - M'!I:I,'JN - M'!$B:$B,">="&EDATE('JN - Q'!$B35,-2),'JN - M'!$B:$B,"<="&EOMONTH('JN - Q'!$B35,0)) -> 3.4885667 | O35: =AVERAGEIFS('JN - M'!J:J,'JN - M'!$B:$B,">="&EDATE('JN - Q'!$B35,-2),'JN - M'!$B:$B,"<="&EOMONTH('JN - Q'!$B35,0)) -> 3.6951554 | S35: =(H35/H31-1)*100+2 -> 2.6264683
B36: 32295 | C36: ='CDM - Q'!M165 -> 392609.53 | G36: =AVERAGEIFS('JN - M'!D:D,'JN - M'!$B:$B,">="&EDATE('JN - Q'!$B36,-2),'JN - M'!$B:$B,"<="&EOMONTH('JN - Q'!$B36,0)) -> 93.219632 | H36: =AVERAGEIFS('JN - M'!E:E,'JN - M'!$B:$B,">="&EDATE('JN - Q'!$B36,-2),'JN - M'!$B:$B,"<="&EOMONTH('JN - Q'!$B36,0)) -> 95.740466 | I36: =AVERAGEIFS('JN - M'!F:F,'JN - M'!$B:$B,">="&EDATE('JN - Q'!$B36,-2),'JN - M'!$B:$B,"<="&EOMONTH('JN - Q'!$B36,0)) -> 95.740466 | J36: =AVERAGEIFS('JN - M'!K:K,'JN - M'!$B:$B,">="&EDATE('JN - Q'!$B36,-2),'JN - M'!$B:$B,"<="&EOMONTH('JN - Q'!$B36,0)) -> 2.4840468 | K36: =K37*S36/S37 -> 1.4434785 | L36: 0 | N36: =AVERAGEIFS('JN - M'!I:I,'JN - M'!$B:$B,">="&EDATE('JN - Q'!$B36,-2),'JN - M'!$B:$B,"<="&EOMONTH('JN - Q'!$B36,0)) -> 3.3323667 | O36: =AVERAGEIFS('JN - M'!J:J,'JN - M'!$B:$B,">="&EDATE('JN - Q'!$B36,-2),'JN - M'!$B:$B,"<="&EOMONTH('JN - Q'!$B36,0)) -> 3.5297054 | S36: =(H36/H32-1)*100+2 -> 2.7392996
B37: 32387 | C37: ='CDM - Q'!M166 -> 401368.44 | G37: =AVERAGEIFS('JN - M'!D:D,'JN - M'!$B:$B,">="&EDATE('JN - Q'!$B37,-2),'JN - M'!$B:$B,"<="&EOMONTH('JN - Q'!$B37,0)) -> 93.395413 | H37: =AVERAGEIFS('JN - M'!E:E,'JN - M'!$B:$B,">="&EDATE('JN - Q'!$B37,-2),'JN - M'!$B:$B,"<="&EOMONTH('JN - Q'!$B37,0)) -> 95.666507 | I37: =AVERAGEIFS('JN - M'!F:F,'JN - M'!$B:$B,">="&EDATE('JN - Q'!$B37,-2),'JN - M'!$B:$B,"<="&EOMONTH('JN - Q'!$B37,0)) -> 95.666507 | J37: =AVERAGEIFS('JN - M'!K:K,'JN - M'!$B:$B,">="&EDATE('JN - Q'!$B37,-2),'JN - M'!$B:$B,"<="&EOMONTH('JN - Q'!$B37,0)) -> 2.5203507 | K37: =K38*S37/S38 -> 1.381839 | L37: 0 | N37: =AVERAGEIFS('JN - M'!I:I,'JN - M'!$B:$B,">="&EDATE('JN - Q'!$B37,-2),'JN - M'!$B:$B,"<="&EOMONTH('JN - Q'!$B37,0)) -> 3.7781333 | O37: =AVERAGEIFS('JN - M'!J:J,'JN - M'!$B:$B,">="&EDATE('JN - Q'!$B37,-2),'JN - M'!$B:$B,"<="&EOMONTH('JN - Q'!$B37,0)) -> 4.0018699 | S37: =(H37/H33-1)*100+2 -> 2.6223259
B38: 32478 | C38: ='CDM - Q'!M167 -> 405598.16 | G38: =AVERAGEIFS('JN - M'!D:D,'JN - M'!$B:$B,">="&EDATE('JN - Q'!$B38,-2),'JN - M'!$B:$B,"<="&EOMONTH('JN - Q'!$B38,0)) -> 93.625668 | H38: =AVERAGEIFS('JN - M'!E:E,'JN - M'!$B:$B,">="&EDATE('JN - Q'!$B38,-2),'JN - M'!$B:$B,"<="&EOMONTH('JN - Q'!$B38,0)) -> 96.295162 | I38: =AVERAGEIFS('JN - M'!F:F,'JN - M'!$B:$B,">="&EDATE('JN - Q'!$B38,-2),'JN - M'!$B:$B,"<="&EOMONTH('JN - Q'!$B38,0)) -> 96.295162 | J38: =AVERAGEIFS('JN - M'!K:K,'JN - M'!$B:$B,">="&EDATE('JN - Q'!$B38,-2),'JN - M'!$B:$B,"<="&EOMONTH('JN - Q'!$B38,0)) -> 2.4009921 | K38: =K39*S38/S39 -> 1.5234845 | L38: 0 | N38: =AVERAGEIFS('JN - M'!I:I,'JN - M'!$B:$B,">="&EDATE('JN - Q'!$B38,-2),'JN - M'!$B:$B,"<="&EOMONTH('JN - Q'!$B38,0)) -> 3.8885667 | O38: =AVERAGEIFS('JN - M'!J:J,'JN - M'!$B:$B,">="&EDATE('JN - Q'!$B38,-2),'JN - M'!$B:$B,"<="&EOMONTH('JN - Q'!$B38,0)) -> 4.1188429 | S38: =(H38/H34-1)*100+2 -> 2.8911275
A39: 1989 | B39: 32568 | C39: ='CDM - Q'!M168 -> 416541.36 | G39: =AVERAGEIFS('JN - M'!D:D,'JN - M'!$B:$B,">="&EDATE('JN - Q'!$B39,-2),'JN - M'!$B:$B,"<="&EOMONTH('JN - Q'!$B39,0)) -> 93.925037 | H39: =AVERAGEIFS('JN - M'!E:E,'JN - M'!$B:$B,">="&EDATE('JN - Q'!$B39,-2),'JN - M'!$B:$B,"<="&EOMONTH('JN - Q'!$B39,0)) -> 96.147243 | I39: =AVERAGEIFS('JN - M'!F:F,'JN - M'!$B:$B,">="&EDATE('JN - Q'!$B39,-2),'JN - M'!$B:$B,"<="&EOMONTH('JN - Q'!$B39,0)) -> 96.147243 | J39: =AVERAGEIFS('JN - M'!K:K,'JN - M'!$B:$B,">="&EDATE('JN - Q'!$B39,-2),'JN - M'!$B:$B,"<="&EOMONTH('JN - Q'!$B39,0)) -> 2.3276462 | K39: =K40*S39/S40 -> 1.669022 | L39: 0 | N39: =AVERAGEIFS('JN - M'!I:I,'JN - M'!$B:$B,">="&EDATE('JN - Q'!$B39,-2),'JN - M'!$B:$B,"<="&EOMONTH('JN - Q'!$B39,0)) -> 3.9091633 | O39: =AVERAGEIFS('JN - M'!J:J,'JN - M'!$B:$B,">="&EDATE('JN - Q'!$B39,-2),'JN - M'!$B:$B,"<="&EOMONTH('JN - Q'!$B39,0)) -> 4.1406593 | S39: =(H39/H35-1)*100+2 -> 3.1673152
B40: 32660 | C40: ='CDM - Q'!M169 -> 411102.45 | G40: =AVERAGEIFS('JN - M'!D:D,'JN - M'!$B:$B,">="&EDATE('JN - Q'!$B40,-2),'JN - M'!$B:$B,"<="&EOMONTH('JN - Q'!$B40,0)) -> 92.891018 | H40: =AVERAGEIFS('JN - M'!E:E,'JN - M'!$B:$B,">="&EDATE('JN - Q'!$B40,-2),'JN - M'!$B:$B,"<="&EOMONTH('JN - Q'!$B40,0)) -> 95.644606 | I40: =AVERAGEIFS('JN - M'!F:F,'JN - M'!$B:$B,">="&EDATE('JN - Q'!$B40,-2),'JN - M'!$B:$B,"<="&EOMONTH('JN - Q'!$B40,0)) -> 95.644606 | J40: =AVERAGEIFS('JN - M'!K:K,'JN - M'!$B:$B,">="&EDATE('JN - Q'!$B40,-2),'JN - M'!$B:$B,"<="&EOMONTH('JN - Q'!$B40,0)) -> 2.30018 | K40: =K41*S40/S41 -> 1.0011424 | L40: 0 | N40: =AVERAGEIFS('JN - M'!I:I,'JN - M'!$B:$B,">="&EDATE('JN - Q'!$B40,-2),'JN - M'!$B:$B,"<="&EOMONTH('JN - Q'!$B40,0)) -> 4.3608433 | O40: =AVERAGEIFS('JN - M'!J:J,'JN - M'!$B:$B,">="&EDATE('JN - Q'!$B40,-2),'JN - M'!$B:$B,"<="&EOMONTH('JN - Q'!$B40,0)) -> 4.6190873 | S40: =(H40/H36-1)*100+2 -> 1.8998751
...

Sheet JN - M
C1: JN Headline | D1: JN Core CPI | E1: JN Core Core CPI | F1: Core Core CPI Forecst | G1: Labour Productivity Index: Manufacturing | H1: Labour Productivity Index: Manufacturing | I1: Interest | J1: SSR | K1: Unemployment Rate | O1: Core CPI History | P1: Core Core CPI History
B2: Date | D2: sa | G2: nsa | H2: sa | K2: sa
A3: =YEAR(B3) -> 1980 | B3: 29221 | D3: =D4*$O3/$O4 -> 77.001651 | E3: =E4*$P3/$P4 -> 77.435511 | F3: =E3 -> 77.435511 | I3: 8.0571 | K3: 1.926851 | O3: 77.099432 | P3: 76.281934
B4: 29252 | D4: =D5*$O4/$O5 -> 77.641118 | E4: =E5*$P4/$P5 -> 77.435511 | F4: =E4 -> 77.435511 | I4: 8.7396 | K4: 1.8360071 | O4: 77.739712 | P4: 76.281934
B5: 29281 | D5: =D6*$O5/$O6 -> 78.100384 | E5: =E6*$P5/$P6 -> 77.990206 | F5: =E5 -> 77.990206 | I5: 10.73 | J5: =J6*I5/I6 -> 11.365418 | K5: 1.886121 | O5: 78.199561 | P5: 76.828366
B6: 29312 | D6: =D7*$O6/$O7 -> 79.420005 | E6: =E7*$P6/$P7 -> 78.988658 | F6: =E6 -> 78.988658 | I6: 12.21 | J6: =J7*I6/I7 -> 12.933062 | K6: 1.9524317 | O6: 79.520858 | P6: 77.811944
B7: 29342 | D7: =D8*$O7/$O8 -> 80.073734 | E7: =E8*$P7/$P8 -> 80.208989 | F7: =E7 -> 80.208989 | I7: 12.5625 | J7: =J8*I7/I8 -> 13.306436 | K7: 1.9572954 | O7: 80.175417 | P7: 79.014095
B8: 29373 | D8: =D9*$O8/$O9 -> 80.539593 | E8: =E9*$P8/$P9 -> 80.652745 | F8: =E8 -> 80.652745 | I8: 12.6425 | J8: =J9*I8/I9 -> 13.391174 | K8: 1.9111662 | O8: 80.641867 | P8: 79.45124
B9: 29403 | D9: =D10*$O9/$O10 -> 80.986919 | E9: =E10*$P9/$P10 -> 80.874623 | F9: =E9 -> 80.874623 | I9: 12.7014 | J9: =J10*I9/I10 -> 13.453562 | K9: 2.0796616 | O9: 81.089761 | P9: 79.669813
B10: 29434 | D10: =D11*$O10/$O11 -> 81.139797 | E10: =E11*$P10/$P11 -> 80.430867 | F10: =E10 -> 80.430867 | I10: 12.0865 | J10: =J11*I10/I11 -> 12.802248 | K10: 2.0796616 | O10: 81.242834 | P10: 79.232668
B11: 29465 | D11: =D12*$O11/$O12 -> 81.352261 | E11: =E12*$P11/$P12 -> 81.31838 | F11: =E11 -> 81.31838 | I11: 11.4036 | J11: =J12*I11/I12 -> 12.078908 | K11: 2.0221558 | O11: 81.455568 | P11: 80.106959
B12: 29495 | D12: =D13*$O12/$O13 -> 81.823243 | E12: =E13*$P12/$P13 -> 81.873076 | F12: =E12 -> 81.873076 | I12: 11.0361 | J12: =J13*I12/I13 -> 11.689645 | K12: 2.0796616 | O12: 81.927148 | P12: 80.653391
B13: 29526 | D13: =D14*$O13/$O14 -> 82.140462 | E13: =E14*$P13/$P14 -> 82.094954 | F13: =E13 -> 82.094954 | I13: 9.5 | J13: =J14*I13/I14 -> 10.062579 | K13: 2.2378855 | O13: 82.244769 | P13: 80.871964
B14: 29556 | D14: =D15*$O14/$O15 -> 82.343751 | E14: =E15*$P14/$P15 -> 82.316832 | F14: =E14 -> 82.316832 | I14: 9.4884 | J14: =J15*I14/I15 -> 10.050292 | K14: 2.2026432 | O14: 82.448317 | P14: 81.090537
A15: =YEAR(B15) -> 1981 | B15: 29587 | D15: =D16*$O15/$O16 -> 82.68632 | E15: =E16*$P15/$P16 -> 82.316832 | F15: =E15 -> 82.316832 | I15: 8.9076 | J15: =J16*I15/I16 -> 9.4350974 | K15: 2.1089631 | O15: 82.791321 | P15: 81.090537
B16: 29618 | D16: =D17*$O16/$O17 -> 82.915602 | E16: =E17*$P16/$P17 -> 82.094954 | F16: =E16 -> 82.094954 | I16: 8.6033 | J16: =J17*I16/I17 -> 9.1127772 | K16: 2.2491653 | O16: 83.020894 | P16: 80.871964
